Workbook

Sheet Results_from_Source
C2: Run 1 | N2: TOTAL
A3: Sim 1 | C3: Echelon | D3: Cost Type | E3: Baseline | F3: ELV | G3: Delta - Baseline | H3: CRP | I3: Delta - Baseline | J3: Delta - ELV | N3: Echelon | O3: Cost Type | P3: Baseline | Q3: ELV | R3: Baseline | S3: S10 | T3: CRP | U3: Baseline | V3: S10 | W3: ELV
C4: Run 1 | D4: Total Costs | E4: 2286 | F4: 957.5 | G4: 0.58114611 | H4: 740.5 | I4: 0.67607174 | J4: 0.094925634 | N4: TOTAL | O4: Total Costs | P4: =SUM(P5:P8) -> 2286 | Q4: =SUM(Q5:Q8) -> 880.4 | R4: =AVERAGE(R5:R8) -> 0.60960775 | S4: =_xlfn.STDEV.S(F4,F12,F20,F28,F36,F44,F52,F60,F68,F76) -> 166.10736 | T4: =SUM(T5:T8) -> 799.1 | U4: =(P4-T4)/P4 -> 0.65043745 | V4: =_xlfn.STDEV.S(H4,H12,H20,H28,H36) -> 52.77381 | W4: =U4-Table1[[#This Row],[ Baseline]] -> 0.040829697
C5: Retailer | D5: Total Costs | E5: 516.5 | F5: 311.5 | G5: 0.39690223 | H5: 172.5 | I5: 0.6660213 | J5: 0.26911907 | N5: Retailer | O5: Total Costs | P5: =AVERAGE(E5,E13,E21,E29,E37,E45,E53,E61,E69,E77) -> 516.5 | Q5: =AVERAGE(F5,F13,F21,F29,F37,F45,F53,F61,F69,F77) -> 202.55 | R5: =(P5-Q5)/P5 -> 0.60784124 | S5: =_xlfn.STDEV.S(F5,F13,F21,F29,F37,F45,F53,F61,F69,F77) -> 67.229065 | T5: =AVERAGE(H5,H13,H21,H29,H37,H45,H53,H61,H69,H77) -> 183.55 | U5: =(P5-T5)/P5 -> 0.6446273 | V5: =_xlfn.STDEV.S(H5,H13,H21,H29,H37) -> 47.443387 | W5: =U5-Table1[[#This Row],[ Baseline]] -> 0.03678606
C6: Wholesaler | D6: Total Costs | E6: 600 | F6: 183 | G6: 0.695 | H6: 180.5 | I6: 0.69916667 | J6: 0.0041666667 | N6: Wholesaler | O6: Total Costs | P6: =AVERAGE(E6,E14,E22,E30,E38,E46,E54,E62,E70,E78) -> 600 | Q6: =AVERAGE(F6,F14,F22,F30,F38,F46,F54,F62,F70,F78) -> 179.75 | R6: =(P6-Q6)/P6 -> 0.70041667 | S6: =_xlfn.STDEV.S(F6,F14,F22,F30,F38,F46,F54,F62,F70,F78) -> 7.5654551 | T6: =AVERAGE(H6,H14,H22,H30,H38,H46,H54,H62,H70,H78) -> 177.35 | U6: =(P6-T6)/P6 -> 0.70441667 | V6: =_xlfn.STDEV.S(H6,H14,H22,H30,H38) -> 3.0536863 | W6: =U6-Table1[[#This Row],[ Baseline]] -> 0.004
C7: Distributor | D7: Total Costs | E7: 634 | F7: 203 | G7: 0.67981073 | H7: 189 | I7: 0.70189274 | J7: 0.022082019 | N7: Distributor | O7: Total Costs | P7: =AVERAGE(E7,E15,E23,E31,E39,E47,E55,E63,E71,E79) -> 634 | Q7: =AVERAGE(F7,F15,F23,F31,F39,F47,F55,F63,F71,F79) -> 207.95 | R7: =(P7-Q7)/P7 -> 0.67200315 | S7: =_xlfn.STDEV.S(F7,F15,F23,F31,F39,F47,F55,F63,F71,F79) -> 20.612092 | T7: =AVERAGE(H7,H15,H23,H31,H39,H47,H55,H63,H71,H79) -> 203.85 | U7: =(P7-T7)/P7 -> 0.67847003 | V7: =_xlfn.STDEV.S(H7,H15,H23,H31,H39) -> 12.359207 | W7: =U7-Table1[[#This Row],[ Baseline]] -> 0.006466877
C8: Producer | D8: Total Costs | E8: 535.5 | F8: 260 | G8: 0.51447246 | H8: 198.5 | I8: 0.62931839 | J8: 0.11484594 | N8: Producer | O8: Total Costs | P8: =AVERAGE(E8,E16,E24,E32,E40,E48,E56,E64,E72,E80) -> 535.5 | Q8: =AVERAGE(F8,F16,F24,F32,F40,F48,F56,F64,F72,F80) -> 290.15 | R8: =(P8-Q8)/P8 -> 0.45816993 | S8: =_xlfn.STDEV.S(F8,F16,F24,F32,F40,F48,F56,F64,F72,F80) -> 129.72493 | T8: =AVERAGE(H8,H16,H24,H32,H40,H48,H56,H64,H72,H80) -> 234.35 | U8: =(P8-T8)/P8 -> 0.56237162 | V8: =_xlfn.STDEV.S(H8,H16,H24,H32,H40) -> 28.674902 | W8: =U8-Table1[[#This Row],[ Baseline]] -> 0.10420168
C10: Run2
A11: Sim 2 | C11: Echelon | D11: Cost Type | E11: Baseline | F11: ELV | G11: Delta - Baseline | H11: CRP | I11: Delta - Baseline | J11: Delta - ELV
C12: Run 2 | D12: Total Costs | E12: 2286 | F12: 817.5 | G12: 0.64238845 | H12: 727.5 | I12: 0.68175853 | J12: 0.039370079
C13: Retailer | D13: Total Costs | E13: 516.5 | F13: 173.5 | G13: 0.66408519 | H13: 178 | I13: 0.6553727 | J13: -0.0087124879
C14: Wholesaler | D14: Total Costs | E14: 600 | F14: 187.5 | G14: 0.6875 | H14: 180 | I14: 0.7 | J14: 0.0125
C15: Distributor | D15: Total Costs | E15: 634 | F15: 217.5 | G15: 0.65694006 | H15: 209 | I15: 0.670347 | J15: 0.01340694
C16: Producer | D16: Total Costs | E16: 535.5 | F16: 239 | G16: 0.55368814 | H16: 160.5 | I16: 0.70028011 | J16: 0.14659197
C18: Run 3
A19: Sim 3 | C19: Echelon | D19: Cost Type | E19: Baseline | F19: ELV | G19: Delta - Baseline | H19: CRP | I19: Delta - Baseline | J19: Delta - ELV
C20: Run 3 | D20: Total Costs | E20: 2286 | F20: 914 | G20: 0.60017498 | H20: 750 | I20: 0.67191601 | J20: 0.071741032
C21: Retailer | D21: Total Costs | E21: 516.5 | F21: 236 | G21: 0.54307841 | H21: 184.5 | I21: 0.642788 | J21: 0.099709584
C22: Wholesaler | D22: Total Costs | E22: 600 | F22: 197 | G22: 0.67166667 | H22: 179.5 | I22: 0.70083333 | J22: 0.029166667
C23: Distributor | D23: Total Costs | E23: 634 | F23: 223.5 | G23: 0.64747634 | H23: 188 | I23: 0.70347003 | J23: 0.055993691
C24: Producer | D24: Total Costs | E24: 535.5 | F24: 257.5 | G24: 0.51914099 | H24: 198 | I24: 0.6302521 | J24: 0.11111111
C26: Run 4
A27: Sim 4 | C27: Echelon | D27: Cost Type | E27: Baseline | F27: ELV | G27: Delta - Baseline | H27: CRP | I27: Delta - Baseline | J27: Delta - ELV
C28: Run 4 | D28: Total Costs | E28: 2286 | F28: 913.5 | G28: 0.6003937 | H28: 815.5 | I28: 0.64326334 | J28: 0.042869641
C29: Retailer | D29: Total Costs | E29: 516.5 | F29: 212 | G29: 0.58954501 | H29: 175.5 | I29: 0.66021297 | J29: 0.070667957
C30: Wholesaler | D30: Total Costs | E30: 600 | F30: 177 | G30: 0.705 | H30: 185 | I30: 0.69166667 | J30: -0.013333333
C31: Distributor | D31: Total Costs | E31: 634 | F31: 212.5 | G31: 0.6648265 | H31: 215.5 | I31: 0.66009464 | J31: -0.0047318612
C32: Producer | D32: Total Costs | E32: 535.5 | F32: 312 | G32: 0.41736695 | H32: 239.5 | I32: 0.55275444 | J32: 0.13538749
C34: Run 5
A35: Sim 5 | C35: Echelon | D35: Cost Type | E35: Baseline | F35: ELV | G35: Delta - Baseline | H35: CRP | I35: Delta - Baseline | J35: Delta - ELV
C36: Run 5 | D36: Total Costs | E36: 2286 | F36: 896.5 | G36: 0.60783027 | H36: 668 | I36: 0.70778653 | J36: 0.099956255
C37: Retailer | D37: Total Costs | E37: 516.5 | F37: 208 | G37: 0.59728945 | H37: 72 | I37: 0.86060019 | J37: 0.26331075
C38: Wholesaler | D38: Total Costs | E38: 600 | F38: 180 | G38: 0.7 | H38: 176.5 | I38: 0.70583333 | J38: 0.0058333333
C39: Distributor | D39: Total Costs | E39: 634 | F39: 194 | G39: 0.69400631 | H39: 206 | I39: 0.67507886 | J39: -0.018927445
C40: Producer | D40: Total Costs | E40: 535.5 | F40: 314.5 | G40: 0.41269841 | H40: 213.5 | I40: 0.60130719 | J40: 0.18860878
C42: Run 6
A43: Sim 6 | C43: Echelon | D43: Cost Type | E43: Baseline | F43: ELV | G43: Delta - Baseline | H43: CRP | I43: Delta - Baseline | J43: Delta - ELV
C44: Run 6 | D44: Total Costs | E44: 2286 | F44: 774.5 | G44: 0.6611986 | H44: 822.5 | I44: 0.64020122 | J44: -0.020997375
C45: Retailer | D45: Total Costs | E45: 516.5 | F45: 212 | G45: 0.58954501 | H45: 212 | I45: 0.58954501 | J45: 0
C46: Wholesaler | D46: Total Costs | E46: 600 | F46: 174 | G46: 0.71 | H46: 172.5 | I46: 0.7125 | J46: 0.0025
...

Sheet Results_Calculated
C2: Run 1 | O2: TOTAL
A3: Sim 1 | C3: Echelon | D3: Cost Type | E3: Baseline | F3: DQN | G3: Delta-Baseline | H3: ELV | I3: Delta - Baseline | J3: CRP | K3: Delta - Baseline | L3: Delta - ELV | M3: Delta- DQN | Q3: Echelon | R3: Baseline | S3: DQN | T3: BL-DQN | U3: ELV | W3: BL - ELV | X3: CRP | Z3: BL - CRP | AA3: ELV- CRP | AB3: DQN-CRP
C4: Run 1 | D4: Total Costs | E4: =SUM(E5:E8) -> 2286 | F4: 788.5 | G4: =(Table619[[#This Row],[Baseline]]-Table619[[#This Row],[DQN]])/Table619[[#This Row],[Baseline]] -> 0.65507437 | H4: =SUM(H5:H8) -> 830 | I4: =(Table619[[#This Row],[Baseline]]-Table619[[#This Row],[ELV]])/E4 -> 0.63692038 | J4: =SUM(J5:J8) -> 930 | K4: =(Table619[[#This Row],[Baseline]]-Table619[[#This Row],[CRP]])/Table619[[#This Row],[Baseline]] -> 0.59317585 | L4: =Table619[[#This Row],[Delta - Baseline ]]-Table619[[#This Row],[Delta - Baseline]] -> -0.043744532 | M4: =Table619[[#This Row],[Delta - Baseline ]]-Table619[[#This Row],[Delta-Baseline]] -> -0.061898513 | Q4: TOTAL | R4: =SUM(R5:R8) -> 2286 | S4: ='Totals All'!AD38 -> 788.5 | T4: =(Table118[[#This Row],[Baseline]]-Table118[[#This Row],[DQN]])/Table118[[#This Row],[Baseline]] -> 0.65507437 | U4: =SUM(U5:U8) -> 891.05 | V4: =_xlfn.STDEV.S(H4,H12,H20,H28,H36,H44,H52,H60,H68,H76) -> 110.39561 | W4: =AVERAGE(W5:W8) -> 0.60363248 | X4: =SUM(X5:X8) -> 860.15 | Y4: =_xlfn.STDEV.S(J4,J12,J20,J28,J36,J44,J52,HK60,J68,J76) -> 80.105009 | Z4: =(R4-X4)/R4 -> 0.62373141 | AA4: =Z4-Table118[[#This Row],[BL - ELV]] -> 0.020098925 | AB4: =Table118[[#This Row],[BL - CRP]]-Table118[[#This Row],[BL-DQN]] -> -0.031342957
C5: Retailer | D5: Total Costs | E5: ='IHC Baseline'!B$40+'UBC Baseline'!B$40 -> 634 | F5: 118 | G5: =(Table619[[#This Row],[Baseline]]-Table619[[#This Row],[DQN]])/Table619[[#This Row],[Baseline]] -> 0.81388013 | H5: ='IHC ELV'!B$40+'UBC ELV'!B$40 -> 193.5 | I5: =(Table619[[#This Row],[Baseline]]-Table619[[#This Row],[ELV]])/E5 -> 0.69479495 | J5: ='IHC CRP'!B$40+'UBC CRP'!B$40 -> 188 | K5: =(Table619[[#This Row],[Baseline]]-Table619[[#This Row],[CRP]])/Table619[[#This Row],[Baseline]] -> 0.70347003 | L5: =Table619[[#This Row],[Delta - Baseline ]]-Table619[[#This Row],[Delta - Baseline]] -> 0.0086750789 | M5: =Table619[[#This Row],[Delta - Baseline ]]-Table619[[#This Row],[Delta-Baseline]] -> -0.11041009 | Q5: Retailer | R5: =AVERAGE(E5,E13,E21,E29,E37,E45,E53,E61,E69,E77) -> 634 | S5: ='Totals DQN'!AA38 -> 118 | T5: =(Table118[[#This Row],[Baseline]]-Table118[[#This Row],[DQN]])/Table118[[#This Row],[Baseline]] -> 0.81388013 | U5: =AVERAGE(H5,H13,H21,H29,H37,H45,H53,H61,H69,H77) -> 195.8 | V5: =_xlfn.STDEV.S(H5,H13,H21,H29,H37,H45,H53,H61,H69,H77) -> 22.859717 | W5: =(R5-U5)/R5 -> 0.69116719 | X5: =AVERAGE(J5,J13,J21,J29,J37,J45,J53,J61,J69,J77) -> 187.7 | Y5: =_xlfn.STDEV.S(J5,J13,J21,J29,J37,J45,J53,HK61,J69,J77) -> 5.6316319 | Z5: =(R5-X5)/R5 -> 0.70394322 | AA5: =Z5-Table118[[#This Row],[BL - ELV]] -> 0.012776025 | AB5: =Table118[[#This Row],[BL - CRP]]-Table118[[#This Row],[BL-DQN]] -> -0.10993691
C6: Wholesaler | D6: Total Costs | E6: ='IHC Baseline'!C$40+'UBC Baseline'!C$40 -> 535.5 | F6: 212.5 | G6: =(Table619[[#This Row],[Baseline]]-Table619[[#This Row],[DQN]])/Table619[[#This Row],[Baseline]] -> 0.6031746 | H6: ='IHC ELV'!C$40+'UBC ELV'!C$40 -> 227 | I6: =(Table619[[#This Row],[Baseline]]-Table619[[#This Row],[ELV]])/E6 -> 0.57609711 | J6: ='IHC CRP'!C$40+'UBC CRP'!C$40 -> 325.5 | K6: =(Table619[[#This Row],[Baseline]]-Table619[[#This Row],[CRP]])/Table619[[#This Row],[Baseline]] -> 0.39215686 | L6: =Table619[[#This Row],[Delta - Baseline ]]-Table619[[#This Row],[Delta - Baseline]] -> -0.18394024 | M6: =Table619[[#This Row],[Delta - Baseline ]]-Table619[[#This Row],[Delta-Baseline]] -> -0.21101774 | Q6: Wholesaler | R6: =AVERAGE(E6,E14,E22,E30,E38,E46,E54,E62,E70,E78) -> 535.5 | S6: ='Totals DQN'!AB38 -> 212.5 | T6: =(Table118[[#This Row],[Baseline]]-Table118[[#This Row],[DQN]])/Table118[[#This Row],[Baseline]] -> 0.6031746 | U6: =AVERAGE(H6,H14,H22,H30,H38,H46,H54,H62,H70,H78) -> 300.55 | V6: =_xlfn.STDEV.S(H6,H14,H22,H30,H38,H46,H54,H62,H70,H78) -> 94.52673 | W6: =(R6-U6)/R6 -> 0.43874883 | X6: =AVERAGE(J6,J14,J22,J30,J38,J46,J54,J62,J70,J78) -> 273.75 | Y6: =_xlfn.STDEV.S(J6,J14,J22,J30,J38,J46,J54,HK62,J70,J78) -> 68.29623 | Z6: =(R6-X6)/R6 -> 0.48879552 | AA6: =Z6-Table118[[#This Row],[BL - ELV]] -> 0.050046685 | AB6: =Table118[[#This Row],[BL - CRP]]-Table118[[#This Row],[BL-DQN]] -> -0.11437908
C7: Distributor | D7: Total Costs | E7: ='IHC Baseline'!D$40+'UBC Baseline'!D$40 -> 516.5 | F7: 297 | G7: =(Table619[[#This Row],[Baseline]]-Table619[[#This Row],[DQN]])/Table619[[#This Row],[Baseline]] -> 0.4249758 | H7: ='IHC ELV'!D$40+'UBC ELV'!D$40 -> 220.5 | I7: =(Table619[[#This Row],[Baseline]]-Table619[[#This Row],[ELV]])/E7 -> 0.57308809 | J7: ='IHC CRP'!D$40+'UBC CRP'!D$40 -> 226.5 | K7: =(Table619[[#This Row],[Baseline]]-Table619[[#This Row],[CRP]])/Table619[[#This Row],[Baseline]] -> 0.56147144 | L7: =Table619[[#This Row],[Delta - Baseline ]]-Table619[[#This Row],[Delta - Baseline]] -> -0.011616651 | M7: =Table619[[#This Row],[Delta - Baseline ]]-Table619[[#This Row],[Delta-Baseline]] -> 0.13649564 | Q7: Distributor | R7: =AVERAGE(E7,E15,E23,E31,E39,E47,E55,E63,E71,E79) -> 516.5 | S7: ='Totals DQN'!AC38 -> 297 | T7: =(Table118[[#This Row],[Baseline]]-Table118[[#This Row],[DQN]])/Table118[[#This Row],[Baseline]] -> 0.4249758 | U7: =AVERAGE(H7,H15,H23,H31,H39,H47,H55,H63,H71,H79) -> 213.6 | V7: =_xlfn.STDEV.S(H7,H15,H23,H31,H39,H47,H55,H63,H71,H79) -> 20.008054 | W7: =(R7-U7)/R7 -> 0.58644724 | X7: =AVERAGE(J7,J15,J23,J31,J39,J47,J55,J63,J71,J79) -> 214.4 | Y7: =_xlfn.STDEV.S(J7,J15,J23,J31,J39,J47,J55,HK63,J71,J79) -> 22.339862 | Z7: =(R7-X7)/R7 -> 0.58489835 | AA7: =Z7-Table118[[#This Row],[BL - ELV]] -> -0.0015488867 | AB7: =Table118[[#This Row],[BL - CRP]]-Table118[[#This Row],[BL-DQN]] -> 0.15992256
C8: Producer | D8: Total Costs | E8: ='IHC Baseline'!E$40+'UBC Baseline'!E$40 -> 600 | F8: 161 | G8: =(Table619[[#This Row],[Baseline]]-Table619[[#This Row],[DQN]])/Table619[[#This Row],[Baseline]] -> 0.73166667 | H8: ='IHC ELV'!E$40+'UBC ELV'!E$40 -> 189 | I8: =(Table619[[#This Row],[Baseline]]-Table619[[#This Row],[ELV]])/E8 -> 0.685 | J8: ='IHC CRP'!E$40+'UBC CRP'!E$40 -> 190 | K8: =(Table619[[#This Row],[Baseline]]-Table619[[#This Row],[CRP]])/Table619[[#This Row],[Baseline]] -> 0.68333333 | L8: =Table619[[#This Row],[Delta - Baseline ]]-Table619[[#This Row],[Delta - Baseline]] -> -0.0016666667 | M8: =Table619[[#This Row],[Delta - Baseline ]]-Table619[[#This Row],[Delta-Baseline]] -> -0.048333333 | Q8: Producer | R8: =AVERAGE(E8,E16,E24,E32,E40,E48,E56,E64,E72,E80) -> 600 | S8: ='Totals DQN'!AD38 -> 161 | T8: =(Table118[[#This Row],[Baseline]]-Table118[[#This Row],[DQN]])/Table118[[#This Row],[Baseline]] -> 0.73166667 | U8: =AVERAGE(H8,H16,H24,H32,H40,H48,H56,H64,H72,H80) -> 181.1 | V8: =_xlfn.STDEV.S(H8,H16,H24,H32,H40,H48,H56,H64,H72,H80) -> 7.7452494 | W8: =(R8-U8)/R8 -> 0.69816667 | X8: =AVERAGE(J8,J16,J24,J32,J40,J48,J56,J64,J72,J80) -> 184.3 | Y8: =_xlfn.STDEV.S(J8,J16,J24,J32,J40,J48,J56,HK64,J72,J80) -> 9.1035707 | Z8: =(R8-X8)/R8 -> 0.69283333 | AA8: =Z8-Table118[[#This Row],[BL - ELV]] -> -0.0053333333 | AB8: =Table118[[#This Row],[BL - CRP]]-Table118[[#This Row],[BL-DQN]] -> -0.038833333
C10: Run2
A11: Sim 2 | C11: Echelon | D11: Cost Type | E11: Baseline | F11: DQN | G11: Delta-Baseline | H11: ELV | I11: Delta - Baseline | J11: CRP | K11: Delta - Baseline | L11: Delta - ELV | M11: Delta - DQN
C12: Run 2 | D12: Total Costs | E12: =SUM(E13:E16) -> 2286 | F12: 788.5 | G12: =(Table720[[#This Row],[Baseline]]-Table720[[#This Row],[DQN]])/Table720[[#This Row],[Baseline]] -> 0.65507437 | H12: =SUM(H13:H16) -> 958 | I12: =(E12-H12)/E12 -> 0.58092738 | J12: =SUM(J13:J16) -> 872.5 | K12: =(E12-J12)/E12 -> 0.61832896 | L12: =K12-I12 -> 0.037401575 | M12: =Table720[[#This Row],[Delta-Baseline]]-Table720[[#This Row],[Delta - Baseline ]] -> 0.036745407
C13: Retailer | D13: Total Costs | E13: ='IHC Baseline'!G$40+'UBC Baseline'!G$40 -> 634 | F13: 118 | G13: =(Table720[[#This Row],[Baseline]]-Table720[[#This Row],[DQN]])/Table720[[#This Row],[Baseline]] -> 0.81388013 | H13: ='IHC ELV'!G$40+'UBC ELV'!G$40 -> 181.5 | I13: =(E13-H13)/E13 -> 0.7137224 | J13: ='IHC CRP'!G$40+'UBC CRP'!G$40 -> 189.5 | K13: =(E13-J13)/E13 -> 0.7011041 | L13: =K13-I13 -> -0.012618297 | M13: =Table720[[#This Row],[Delta-Baseline]]-Table720[[#This Row],[Delta - Baseline ]] -> 0.11277603
C14: Wholesaler | D14: Total Costs | E14: ='IHC Baseline'!H$40+'UBC Baseline'!H$40 -> 535.5 | F14: 212.5 | G14: =(Table720[[#This Row],[Baseline]]-Table720[[#This Row],[DQN]])/Table720[[#This Row],[Baseline]] -> 0.6031746 | H14: ='IHC ELV'!H$40+'UBC ELV'!H$40 -> 374.5 | I14: =(E14-H14)/E14 -> 0.30065359 | J14: ='IHC CRP'!H$40+'UBC CRP'!H$40 -> 269 | K14: =(E14-J14)/E14 -> 0.49766573 | L14: =K14-I14 -> 0.19701214 | M14: =Table720[[#This Row],[Delta-Baseline]]-Table720[[#This Row],[Delta - Baseline ]] -> 0.10550887
C15: Distributor | D15: Total Costs | E15: ='IHC Baseline'!I$40+'UBC Baseline'!I$40 -> 516.5 | F15: 297 | G15: =(Table720[[#This Row],[Baseline]]-Table720[[#This Row],[DQN]])/Table720[[#This Row],[Baseline]] -> 0.4249758 | H15: ='IHC ELV'!I$40+'UBC ELV'!I$40 -> 219 | I15: =(E15-H15)/E15 -> 0.57599226 | J15: ='IHC CRP'!I$40+'UBC CRP'!I$40 -> 227.5 | K15: =(E15-J15)/E15 -> 0.55953533 | L15: =K15-I15 -> -0.016456922 | M15: =Table720[[#This Row],[Delta-Baseline]]-Table720[[#This Row],[Delta - Baseline ]] -> -0.13455954
C16: Producer | D16: Total Costs | E16: ='IHC Baseline'!J$40+'UBC Baseline'!J$40 -> 600 | F16: 161 | G16: =(Table720[[#This Row],[Baseline]]-Table720[[#This Row],[DQN]])/Table720[[#This Row],[Baseline]] -> 0.73166667 | H16: ='IHC ELV'!J$40+'UBC ELV'!J$40 -> 183 | I16: =(E16-H16)/E16 -> 0.695 | J16: ='IHC CRP'!J$40+'UBC CRP'!J$40 -> 186.5 | K16: =(E16-J16)/E16 -> 0.68916667 | L16: =K16-I16 -> -0.0058333333 | M16: =Table720[[#This Row],[Delta-Baseline]]-Table720[[#This Row],[Delta - Baseline ]] -> 0.0425
C18: Run 3
A19: Sim 3 | C19: Echelon | D19: Cost Type | E19: Baseline | H19: ELV | I19: Delta - Baseline | J19: CRP | K19: Delta - Baseline | L19: Delta - ELV | M19: Delta - DQN
C20: Run 3 | D20: Total Costs | E20: =SUM(E21:E24) -> 2286 | F20: 788.5 | G20: =(E20-F20)/E20 -> 0.65507437 | H20: =SUM(H21:H24) -> 936 | I20: =(E20-H20)/E20 -> 0.59055118 | J20: =SUM(J21:J24) -> 801.5 | K20: =(E20-J20)/E20 -> 0.64938758 | L20: =K20-I20 -> 0.058836395 | M20: =G20-K20 -> 0.0056867892
C21: Retailer | D21: Total Costs | E21: ='IHC Baseline'!L$40+'UBC Baseline'!L$40 -> 634 | F21: 118 | G21: =(E21-F21)/E21 -> 0.81388013 | H21: ='IHC ELV'!L$40+'UBC ELV'!L$40 -> 182 | I21: =(E21-H21)/E21 -> 0.71293375 | J21: ='IHC CRP'!L$40+'UBC CRP'!L$40 -> 181.5 | K21: =(E21-J21)/E21 -> 0.7137224 | L21: =K21-I21 -> 0.00078864353 | M21: =G21-K21 -> 0.10015773
C22: Wholesaler | D22: Total Costs | E22: ='IHC Baseline'!M$40+'UBC Baseline'!M$40 -> 535.5 | F22: 212.5 | G22: =(E22-F22)/E22 -> 0.6031746 | H22: ='IHC ELV'!M$40+'UBC ELV'!M$40 -> 350 | I22: =(E22-H22)/E22 -> 0.34640523 | J22: ='IHC CRP'!M$40+'UBC CRP'!M$40 -> 208.5 | K22: =(E22-J22)/E22 -> 0.61064426 | L22: =K22-I22 -> 0.26423903 | M22: =G22-K22 -> -0.0074696545
C23: Distributor | D23: Total Costs | E23: ='IHC Baseline'!N$40+'UBC Baseline'!N$40 -> 516.5 | F23: 297 | G23: =(E23-F23)/E23 -> 0.4249758 | H23: ='IHC ELV'!N$40+'UBC ELV'!N$40 -> 220.5 | I23: =(E23-H23)/E23 -> 0.57308809 | J23: ='IHC CRP'!N$40+'UBC CRP'!N$40 -> 226.5 | K23: =(E23-J23)/E23 -> 0.56147144 | L23: =K23-I23 -> -0.011616651 | M23: =G23-K23 -> -0.13649564
C24: Producer | D24: Total Costs | E24: ='IHC Baseline'!O$40+'UBC Baseline'!O$40 -> 600 | F24: 161 | G24: =(E24-F24)/E24 -> 0.73166667 | H24: ='IHC ELV'!O$40+'UBC ELV'!O$40 -> 183.5 | I24: =(E24-H24)/E24 -> 0.69416667 | J24: ='IHC CRP'!O$40+'UBC CRP'!O$40 -> 185 | K24: =(E24-J24)/E24 -> 0.69166667 | L24: =K24-I24 -> -0.0025 | M24: =G24-K24 -> 0.04
C26: Run 4
A27: Sim 4 | C27: Echelon | D27: Cost Type | E27: Baseline | H27: ELV | I27: Delta - Baseline | J27: CRP | K27: Delta - Baseline | L27: Delta - ELV | M27: Delta - DQN
C28: Run 4 | D28: Total Costs | E28: =SUM(E29:E32) -> 2286 | F28: 788.5 | G28: =(E28-F28)/E28 -> 0.65507437 | H28: =SUM(H29:H32) -> 847.5 | I28: =(E28-H28)/E28 -> 0.62926509 | J28: =SUM(J29:J32) -> 863 | K28: =(E28-J28)/E28 -> 0.62248469 | L28: =K28-I28 -> -0.0067804024 | M28: =G28-K28 -> 0.032589676
C29: Retailer | D29: Total Costs | E29: ='IHC Baseline'!Q$40+'UBC Baseline'!Q$40 -> 634 | F29: 118 | G29: =(E29-F29)/E29 -> 0.81388013 | H29: ='IHC ELV'!Q$40+'UBC ELV'!Q$40 -> 202 | I29: =(E29-H29)/E29 -> 0.68138801 | J29: ='IHC CRP'!Q$40+'UBC CRP'!Q$40 -> 183 | K29: =(E29-J29)/E29 -> 0.71135647 | L29: =K29-I29 -> 0.029968454 | M29: =G29-K29 -> 0.10252366
C30: Wholesaler | D30: Total Costs | E30: ='IHC Baseline'!R$40+'UBC Baseline'!R$40 -> 535.5 | F30: 212.5 | G30: =(E30-F30)/E30 -> 0.6031746 | H30: ='IHC ELV'!R$40+'UBC ELV'!R$40 -> 238 | I30: =(E30-H30)/E30 -> 0.55555556 | J30: ='IHC CRP'!R$40+'UBC CRP'!R$40 -> 265 | K30: =(E30-J30)/E30 -> 0.50513539 | L30: =K30-I30 -> -0.050420168 | M30: =G30-K30 -> 0.098039216
C31: Distributor | D31: Total Costs | E31: ='IHC Baseline'!S$40+'UBC Baseline'!S$40 -> 516.5 | F31: 297 | G31: =(E31-F31)/E31 -> 0.4249758 | H31: ='IHC ELV'!S$40+'UBC ELV'!S$40 -> 220.5 | I31: =(E31-H31)/E31 -> 0.57308809 | J31: ='IHC CRP'!S$40+'UBC CRP'!S$40 -> 232.5 | K31: =(E31-J31)/E31 -> 0.54985479 | L31: =K31-I31 -> -0.023233301 | M31: =G31-K31 -> -0.12487899
C32: Producer | D32: Total Costs | E32: ='IHC Baseline'!T$40+'UBC Baseline'!T$40 -> 600 | F32: 161 | G32: =(E32-F32)/E32 -> 0.73166667 | H32: ='IHC ELV'!T$40+'UBC ELV'!T$40 -> 187 | I32: =(E32-H32)/E32 -> 0.68833333 | J32: ='IHC CRP'!T$40+'UBC CRP'!T$40 -> 182.5 | K32: =(E32-J32)/E32 -> 0.69583333 | L32: =K32-I32 -> 0.0075 | M32: =G32-K32 -> 0.035833333
C34: Run 5
A35: Sim 5 | C35: Echelon | D35: Cost Type | E35: Baseline | H35: ELV | I35: Delta - Baseline | J35: CRP | K35: Delta - Baseline | L35: Delta - ELV | M35: Delta - DQN
C36: Run 5 | D36: Total Costs | E36: =SUM(E37:E40) -> 2286 | F36: 788.5 | G36: =(E36-F36)/E36 -> 0.65507437 | H36: =SUM(H37:H40) -> 764.5 | I36: =(E36-H36)/E36 -> 0.66557305 | J36: =SUM(J37:J40) -> 865.5 | K36: =(E36-J36)/E36 -> 0.62139108 | L36: =K36-I36 -> -0.044181977 | M36: =G36-K36 -> 0.03368329
C37: Retailer | D37: Total Costs | E37: ='IHC Baseline'!V$40+'UBC Baseline'!V$40 -> 634 | F37: 118 | G37: =(E37-F37)/E37 -> 0.81388013 | H37: ='IHC ELV'!V$40+'UBC ELV'!V$40 -> 207.5 | I37: =(E37-H37)/E37 -> 0.67271293 | J37: ='IHC CRP'!V$40+'UBC CRP'!V$40 -> 185 | K37: =(E37-J37)/E37 -> 0.70820189 | L37: =K37-I37 -> 0.035488959 | M37: =G37-K37 -> 0.10567823
C38: Wholesaler | D38: Total Costs | E38: ='IHC Baseline'!W$40+'UBC Baseline'!W$40 -> 535.5 | F38: 212.5 | G38: =(E38-F38)/E38 -> 0.6031746 | H38: ='IHC ELV'!W$40+'UBC ELV'!W$40 -> 190 | I38: =(E38-H38)/E38 -> 0.64519141 | J38: ='IHC CRP'!W$40+'UBC CRP'!W$40 -> 267.5 | K38: =(E38-J38)/E38 -> 0.50046685 | L38: =K38-I38 -> -0.14472456 | M38: =G38-K38 -> 0.10270775
C39: Distributor | D39: Total Costs | E39: ='IHC Baseline'!X$40+'UBC Baseline'!X$40 -> 516.5 | F39: 297 | G39: =(E39-F39)/E39 -> 0.4249758 | H39: ='IHC ELV'!X$40+'UBC ELV'!X$40 -> 177.5 | I39: =(E39-H39)/E39 -> 0.65634076 | J39: ='IHC CRP'!X$40+'UBC CRP'!X$40 -> 220 | K39: =(E39-J39)/E39 -> 0.57405615 | L39: =K39-I39 -> -0.082284608 | M39: =G39-K39 -> -0.14908035
C40: Producer | D40: Total Costs | E40: ='IHC Baseline'!Y$40+'UBC Baseline'!Y$40 -> 600 | F40: 161 | G40: =(E40-F40)/E40 -> 0.73166667 | H40: ='IHC ELV'!Y$40+'UBC ELV'!Y$40 -> 189.5 | I40: =(E40-H40)/E40 -> 0.68416667 | J40: ='IHC CRP'!Y$40+'UBC CRP'!Y$40 -> 193 | K40: =(E40-J40)/E40 -> 0.67833333 | L40: =K40-I40 -> -0.0058333333 | M40: =G40-K40 -> 0.053333333
C42: Run 6
A43: Sim 6 | C43: Echelon | D43: Cost Type | E43: Baseline | H43: ELV | I43: Delta - Baseline | J43: CRP | K43: Delta - Baseline | L43: Delta - ELV | M43: Delta - DQN
C44: Run 6 | D44: Total Costs | E44: =SUM(E45:E48) -> 2286 | F44: 788.5 | G44: =(E44-F44)/E44 -> 0.65507437 | H44: =SUM(H45:H48) -> 914.5 | I44: =(E44-H44)/E44 -> 0.59995626 | J44: =SUM(J45:J48) -> 865.5 | K44: =(E44-J44)/E44 -> 0.62139108 | L44: =K44-I44 -> 0.021434821 | M44: =G44-K44 -> 0.03368329
C45: Retailer | D45: Total Costs | E45: ='IHC Baseline'!AA$40+'UBC Baseline'!AA$40 -> 634 | F45: 118 | G45: =(E45-F45)/E45 -> 0.81388013 | H45: ='IHC ELV'!AA$40+'UBC ELV'!AA$40 -> 201.5 | I45: =(E45-H45)/E45 -> 0.68217666 | J45: ='IHC CRP'!AA$40+'UBC CRP'!AA$40 -> 185 | K45: =(E45-J45)/E45 -> 0.70820189 | L45: =K45-I45 -> 0.026025237 | M45: =G45-K45 -> 0.10567823
C46: Wholesaler | D46: Total Costs | E46: ='IHC Baseline'!AB$40+'UBC Baseline'!AB$40 -> 535.5 | F46: 212.5 | G46: =(E46-F46)/E46 -> 0.6031746 | H46: ='IHC ELV'!AB$40+'UBC ELV'!AB$40 -> 304.5 | I46: =(E46-H46)/E46 -> 0.43137255 | J46: ='IHC CRP'!AB$40+'UBC CRP'!AB$40 -> 267.5 | K46: =(E46-J46)/E46 -> 0.50046685 | L46: =K46-I46 -> 0.069094304 | M46: =G46-K46 -> 0.10270775
...

Sheet Graphs Total

Sheet Totals All
A1: t | B1: I Baseline | C1: I ELV | D1: I CRP | E1: I DQN | F1: t | G1: B Baseline | H1: B ELV | I1: B CRP | J1: B DQN | K1: t | L1: O Baseline | M1: O ELV | N1: O CRP | O1: O DQN | P1: t | Q1: IHC Baseline | R1: IHC ELV | S1: IHC CRP | T1: IHC DQN | U1: t | V1: UBC Baseline | W1: UBC ELV | X1: UBC CRP | Y1: UBC DQN | Z1: t | AA1: TC Baseline | AB1: TC ELV | AC1: TC CRP | AD1: TC DQN
A2: 0 | B2: =SUM('Totals Baseline'!B2:E2) -> 48 | C2: =SUM('Totals ELV'!B2:E2) -> 48 | D2: =SUM('Totals CRP'!B2:E2) -> 48 | E2: =SUM('Totals DQN'!B2:E2) -> 48 | F2: 0 | G2: =SUM('Totals Baseline'!G2:J2) -> 0 | H2: =SUM('Totals ELV'!G2:J2) -> 0 | I2: =SUM('Totals CRP'!G2:J2) -> 0 | J2: =SUM('Totals DQN'!G2:J2) -> 0 | K2: 0 | L2: =SUM('Totals Baseline'!L2:O2) -> 0 | M2: =SUM('Totals ELV'!L2:O2) -> 0 | N2: =SUM('Totals CRP'!L2:O2) -> 0 | O2: =SUM('Totals DQN'!L2:O2) -> 0 | P2: 0 | Q2: =ROUND(SUM('Totals Baseline'!Q2:T2),0) -> 0 | R2: =ROUND(SUM('Totals ELV'!Q2:T2),0) -> 0 | S2: =ROUND(SUM('Totals CRP'!Q2:T2),0) -> 0 | T2: =ROUND(SUM('Totals DQN'!Q2:T2),0) -> 0 | U2: 0 | V2: =ROUND(SUM('Totals Baseline'!V2:Y2),0) -> 0 | W2: =ROUND(SUM('Totals ELV'!V2:Y2),0) -> 0 | X2: =ROUND(SUM('Totals CRP'!V2:Y2),0) -> 0 | Y2: =ROUND(SUM('Totals DQN'!V2:Y2),0) -> 0 | Z2: 0 | AA2: =SUM('Totals Baseline'!AA2:AD2) -> 0 | AB2: =SUM('Totals ELV'!AA2:AD2) -> 0 | AC2: =SUM('Totals CRP'!AA2:AD2) -> 0 | AD2: =SUM('Totals DQN'!AA2:AD2) -> 0
A3: 1 | B3: =SUM('Totals Baseline'!B3:E3) -> 48 | C3: =SUM('Totals ELV'!B3:E3) -> 48 | D3: =SUM('Totals CRP'!B3:E3) -> 48 | E3: =SUM('Totals DQN'!B3:E3) -> 48 | F3: 1 | G3: =SUM('Totals Baseline'!G3:J3) -> 0 | H3: =SUM('Totals ELV'!G3:J3) -> 0 | I3: =SUM('Totals CRP'!G3:J3) -> 0 | J3: =SUM('Totals DQN'!G3:J3) -> 0 | K3: 1 | L3: =SUM('Totals Baseline'!L3:O3) -> 16 | M3: =SUM('Totals ELV'!L3:O3) -> 16 | N3: =SUM('Totals CRP'!L3:O3) -> 16 | O3: =SUM('Totals DQN'!L3:O3) -> 18 | P3: 1 | Q3: =ROUND(SUM('Totals Baseline'!Q3:T3),0) -> 24 | R3: =ROUND(SUM('Totals ELV'!Q3:T3),0) -> 24 | S3: =ROUND(SUM('Totals CRP'!Q3:T3),0) -> 24 | T3: =ROUND(SUM('Totals DQN'!Q3:T3),0) -> 24 | U3: 1 | V3: =ROUND(SUM('Totals Baseline'!V3:Y3),0) -> 0 | W3: =ROUND(SUM('Totals ELV'!V3:Y3),0) -> 0 | X3: =ROUND(SUM('Totals CRP'!V3:Y3),0) -> 0 | Y3: =ROUND(SUM('Totals DQN'!V3:Y3),0) -> 0 | Z3: 1 | AA3: =SUM('Totals Baseline'!AA3:AD3) -> 24 | AB3: =SUM('Totals ELV'!AA3:AD3) -> 24 | AC3: =SUM('Totals CRP'!AA3:AD3) -> 24 | AD3: =SUM('Totals DQN'!AA3:AD3) -> 24
A4: 2 | B4: =SUM('Totals Baseline'!B4:E4) -> 48 | C4: =SUM('Totals ELV'!B4:E4) -> 68 | D4: =SUM('Totals CRP'!B4:E4) -> 59.6 | E4: =SUM('Totals DQN'!B4:E4) -> 32 | F4: 2 | G4: =SUM('Totals Baseline'!G4:J4) -> 0 | H4: =SUM('Totals ELV'!G4:J4) -> 0 | I4: =SUM('Totals CRP'!G4:J4) -> 0 | J4: =SUM('Totals DQN'!G4:J4) -> 0 | K4: 2 | L4: =SUM('Totals Baseline'!L4:O4) -> 16 | M4: =SUM('Totals ELV'!L4:O4) -> 16 | N4: =SUM('Totals CRP'!L4:O4) -> 16 | O4: =SUM('Totals DQN'!L4:O4) -> 26 | P4: 2 | Q4: =ROUND(SUM('Totals Baseline'!Q4:T4),0) -> 24 | R4: =ROUND(SUM('Totals ELV'!Q4:T4),0) -> 29 | S4: =ROUND(SUM('Totals CRP'!Q4:T4),0) -> 30 | T4: =ROUND(SUM('Totals DQN'!Q4:T4),0) -> 16 | U4: 2 | V4: =ROUND(SUM('Totals Baseline'!V4:Y4),0) -> 0 | W4: =ROUND(SUM('Totals ELV'!V4:Y4),0) -> 0 | X4: =ROUND(SUM('Totals CRP'!V4:Y4),0) -> 0 | Y4: =ROUND(SUM('Totals DQN'!V4:Y4),0) -> 0 | Z4: 2 | AA4: =SUM('Totals Baseline'!AA4:AD4) -> 48 | AB4: =SUM('Totals ELV'!AA4:AD4) -> 53.4 | AC4: =SUM('Totals CRP'!AA4:AD4) -> 53.8 | AD4: =SUM('Totals DQN'!AA4:AD4) -> 40
A5: 3 | B5: =SUM('Totals Baseline'!B5:E5) -> 48 | C5: =SUM('Totals ELV'!B5:E5) -> 48 | D5: =SUM('Totals CRP'!B5:E5) -> 51.2 | E5: =SUM('Totals DQN'!B5:E5) -> 16 | F5: 3 | G5: =SUM('Totals Baseline'!G5:J5) -> 0 | H5: =SUM('Totals ELV'!G5:J5) -> 0 | I5: =SUM('Totals CRP'!G5:J5) -> 0 | J5: =SUM('Totals DQN'!G5:J5) -> 0 | K5: 3 | L5: =SUM('Totals Baseline'!L5:O5) -> 16 | M5: =SUM('Totals ELV'!L5:O5) -> 16 | N5: =SUM('Totals CRP'!L5:O5) -> 16 | O5: =SUM('Totals DQN'!L5:O5) -> 34 | P5: 3 | Q5: =ROUND(SUM('Totals Baseline'!Q5:T5),0) -> 24 | R5: =ROUND(SUM('Totals ELV'!Q5:T5),0) -> 23 | S5: =ROUND(SUM('Totals CRP'!Q5:T5),0) -> 26 | T5: =ROUND(SUM('Totals DQN'!Q5:T5),0) -> 8 | U5: 3 | V5: =ROUND(SUM('Totals Baseline'!V5:Y5),0) -> 0 | W5: =ROUND(SUM('Totals ELV'!V5:Y5),0) -> 0 | X5: =ROUND(SUM('Totals CRP'!V5:Y5),0) -> 0 | Y5: =ROUND(SUM('Totals DQN'!V5:Y5),0) -> 0 | Z5: 3 | AA5: =SUM('Totals Baseline'!AA5:AD5) -> 72 | AB5: =SUM('Totals ELV'!AA5:AD5) -> 76.8 | AC5: =SUM('Totals CRP'!AA5:AD5) -> 79.4 | AD5: =SUM('Totals DQN'!AA5:AD5) -> 48
A6: 4 | B6: =SUM('Totals Baseline'!B6:E6) -> 48 | C6: =SUM('Totals ELV'!B6:E6) -> 48 | D6: =SUM('Totals CRP'!B6:E6) -> 44.4 | E6: =SUM('Totals DQN'!B6:E6) -> 10 | F6: 4 | G6: =SUM('Totals Baseline'!G6:J6) -> 0 | H6: =SUM('Totals ELV'!G6:J6) -> 0 | I6: =SUM('Totals CRP'!G6:J6) -> 0 | J6: =SUM('Totals DQN'!G6:J6) -> 0 | K6: 4 | L6: =SUM('Totals Baseline'!L6:O6) -> 16 | M6: =SUM('Totals ELV'!L6:O6) -> 16 | N6: =SUM('Totals CRP'!L6:O6) -> 16 | O6: =SUM('Totals DQN'!L6:O6) -> 39 | P6: 4 | Q6: =ROUND(SUM('Totals Baseline'!Q6:T6),0) -> 24 | R6: =ROUND(SUM('Totals ELV'!Q6:T6),0) -> 21 | S6: =ROUND(SUM('Totals CRP'!Q6:T6),0) -> 22 | T6: =ROUND(SUM('Totals DQN'!Q6:T6),0) -> 5 | U6: 4 | V6: =ROUND(SUM('Totals Baseline'!V6:Y6),0) -> 0 | W6: =ROUND(SUM('Totals ELV'!V6:Y6),0) -> 0 | X6: =ROUND(SUM('Totals CRP'!V6:Y6),0) -> 0 | Y6: =ROUND(SUM('Totals DQN'!V6:Y6),0) -> 0 | Z6: 4 | AA6: =SUM('Totals Baseline'!AA6:AD6) -> 96 | AB6: =SUM('Totals ELV'!AA6:AD6) -> 98 | AC6: =SUM('Totals CRP'!AA6:AD6) -> 101.6 | AD6: =SUM('Totals DQN'!AA6:AD6) -> 53
A7: 5 | B7: =SUM('Totals Baseline'!B7:E7) -> 44 | C7: =SUM('Totals ELV'!B7:E7) -> 44 | D7: =SUM('Totals CRP'!B7:E7) -> 43.2 | E7: =SUM('Totals DQN'!B7:E7) -> 8 | F7: 5 | G7: =SUM('Totals Baseline'!G7:J7) -> 0 | H7: =SUM('Totals ELV'!G7:J7) -> 0 | I7: =SUM('Totals CRP'!G7:J7) -> 0 | J7: =SUM('Totals DQN'!G7:J7) -> 5 | K7: 5 | L7: =SUM('Totals Baseline'!L7:O7) -> 20 | M7: =SUM('Totals ELV'!L7:O7) -> 20 | N7: =SUM('Totals CRP'!L7:O7) -> 20 | O7: =SUM('Totals DQN'!L7:O7) -> 46 | P7: 5 | Q7: =ROUND(SUM('Totals Baseline'!Q7:T7),0) -> 22 | R7: =ROUND(SUM('Totals ELV'!Q7:T7),0) -> 21 | S7: =ROUND(SUM('Totals CRP'!Q7:T7),0) -> 22 | T7: =ROUND(SUM('Totals DQN'!Q7:T7),0) -> 4 | U7: 5 | V7: =ROUND(SUM('Totals Baseline'!V7:Y7),0) -> 0 | W7: =ROUND(SUM('Totals ELV'!V7:Y7),0) -> 0 | X7: =ROUND(SUM('Totals CRP'!V7:Y7),0) -> 0 | Y7: =ROUND(SUM('Totals DQN'!V7:Y7),0) -> 5 | Z7: 5 | AA7: =SUM('Totals Baseline'!AA7:AD7) -> 118 | AB7: =SUM('Totals ELV'!AA7:AD7) -> 119.2 | AC7: =SUM('Totals CRP'!AA7:AD7) -> 123.2 | AD7: =SUM('Totals DQN'!AA7:AD7) -> 62
A8: 6 | B8: =SUM('Totals Baseline'!B8:E8) -> 40 | C8: =SUM('Totals ELV'!B8:E8) -> 44 | D8: =SUM('Totals CRP'!B8:E8) -> 42.8 | E8: =SUM('Totals DQN'!B8:E8) -> 5 | F8: 6 | G8: =SUM('Totals Baseline'!G8:J8) -> 0 | H8: =SUM('Totals ELV'!G8:J8) -> 0 | I8: =SUM('Totals CRP'!G8:J8) -> 0 | J8: =SUM('Totals DQN'!G8:J8) -> 7 | K8: 6 | L8: =SUM('Totals Baseline'!L8:O8) -> 12 | M8: =SUM('Totals ELV'!L8:O8) -> 14.8 | N8: =SUM('Totals CRP'!L8:O8) -> 15.7 | O8: =SUM('Totals DQN'!L8:O8) -> 49 | P8: 6 | Q8: =ROUND(SUM('Totals Baseline'!Q8:T8),0) -> 20 | R8: =ROUND(SUM('Totals ELV'!Q8:T8),0) -> 21 | S8: =ROUND(SUM('Totals CRP'!Q8:T8),0) -> 21 | T8: =ROUND(SUM('Totals DQN'!Q8:T8),0) -> 3 | U8: 6 | V8: =ROUND(SUM('Totals Baseline'!V8:Y8),0) -> 0 | W8: =ROUND(SUM('Totals ELV'!V8:Y8),0) -> 0 | X8: =ROUND(SUM('Totals CRP'!V8:Y8),0) -> 0 | Y8: =ROUND(SUM('Totals DQN'!V8:Y8),0) -> 7 | Z8: 6 | AA8: =SUM('Totals Baseline'!AA8:AD8) -> 138 | AB8: =SUM('Totals ELV'!AA8:AD8) -> 140.6 | AC8: =SUM('Totals CRP'!AA8:AD8) -> 144.6 | AD8: =SUM('Totals DQN'!AA8:AD8) -> 71.5
A9: 7 | B9: =SUM('Totals Baseline'!B9:E9) -> 44 | C9: =SUM('Totals ELV'!B9:E9) -> 53 | D9: =SUM('Totals CRP'!B9:E9) -> 47.7 | E9: =SUM('Totals DQN'!B9:E9) -> 3 | F9: 7 | G9: =SUM('Totals Baseline'!G9:J9) -> 0 | H9: =SUM('Totals ELV'!G9:J9) -> 0 | I9: =SUM('Totals CRP'!G9:J9) -> 0 | J9: =SUM('Totals DQN'!G9:J9) -> 10 | K9: 7 | L9: =SUM('Totals Baseline'!L9:O9) -> 16 | M9: =SUM('Totals ELV'!L9:O9) -> 18.6 | N9: =SUM('Totals CRP'!L9:O9) -> 17.6 | O9: =SUM('Totals DQN'!L9:O9) -> 51 | P9: 7 | Q9: =ROUND(SUM('Totals Baseline'!Q9:T9),0) -> 22 | R9: =ROUND(SUM('Totals ELV'!Q9:T9),0) -> 24 | S9: =ROUND(SUM('Totals CRP'!Q9:T9),0) -> 24 | T9: =ROUND(SUM('Totals DQN'!Q9:T9),0) -> 2 | U9: 7 | V9: =ROUND(SUM('Totals Baseline'!V9:Y9),0) -> 0 | W9: =ROUND(SUM('Totals ELV'!V9:Y9),0) -> 0 | X9: =ROUND(SUM('Totals CRP'!V9:Y9),0) -> 0 | Y9: =ROUND(SUM('Totals DQN'!V9:Y9),0) -> 10 | Z9: 7 | AA9: =SUM('Totals Baseline'!AA9:AD9) -> 160 | AB9: =SUM('Totals ELV'!AA9:AD9) -> 165 | AC9: =SUM('Totals CRP'!AA9:AD9) -> 168.45 | AD9: =SUM('Totals DQN'!AA9:AD9) -> 83
A10: 8 | B10: =SUM('Totals Baseline'!B10:E10) -> 44 | C10: =SUM('Totals ELV'!B10:E10) -> 43 | D10: =SUM('Totals CRP'!B10:E10) -> 42.8 | E10: =SUM('Totals DQN'!B10:E10) -> 4 | F10: 8 | G10: =SUM('Totals Baseline'!G10:J10) -> 4 | H10: =SUM('Totals ELV'!G10:J10) -> 0 | I10: =SUM('Totals CRP'!G10:J10) -> 0 | J10: =SUM('Totals DQN'!G10:J10) -> 12 | K10: 8 | L10: =SUM('Totals Baseline'!L10:O10) -> 18 | M10: =SUM('Totals ELV'!L10:O10) -> 25.8 | N10: =SUM('Totals CRP'!L10:O10) -> 25.9 | O10: =SUM('Totals DQN'!L10:O10) -> 52 | P10: 8 | Q10: =ROUND(SUM('Totals Baseline'!Q10:T10),0) -> 22 | R10: =ROUND(SUM('Totals ELV'!Q10:T10),0) -> 21 | S10: =ROUND(SUM('Totals CRP'!Q10:T10),0) -> 21 | T10: =ROUND(SUM('Totals DQN'!Q10:T10),0) -> 2 | U10: 8 | V10: =ROUND(SUM('Totals Baseline'!V10:Y10),0) -> 4 | W10: =ROUND(SUM('Totals ELV'!V10:Y10),0) -> 0 | X10: =ROUND(SUM('Totals CRP'!V10:Y10),0) -> 0 | Y10: =ROUND(SUM('Totals DQN'!V10:Y10),0) -> 12 | Z10: 8 | AA10: =SUM('Totals Baseline'!AA10:AD10) -> 186 | AB10: =SUM('Totals ELV'!AA10:AD10) -> 185.9 | AC10: =SUM('Totals CRP'!AA10:AD10) -> 189.85 | AD10: =SUM('Totals DQN'!AA10:AD10) -> 97
A11: 9 | B11: =SUM('Totals Baseline'!B11:E11) -> 35 | C11: =SUM('Totals ELV'!B11:E11) -> 33 | D11: =SUM('Totals CRP'!B11:E11) -> 31 | E11: =SUM('Totals DQN'!B11:E11) -> 4 | F11: 9 | G11: =SUM('Totals Baseline'!G11:J11) -> 9 | H11: =SUM('Totals ELV'!G11:J11) -> 1.5 | I11: =SUM('Totals CRP'!G11:J11) -> 0.3 | J11: =SUM('Totals DQN'!G11:J11) -> 14 | K11: 9 | L11: =SUM('Totals Baseline'!L11:O11) -> 26 | M11: =SUM('Totals ELV'!L11:O11) -> 29.2 | N11: =SUM('Totals CRP'!L11:O11) -> 29.4 | O11: =SUM('Totals DQN'!L11:O11) -> 51 | P11: 9 | Q11: =ROUND(SUM('Totals Baseline'!Q11:T11),0) -> 18 | R11: =ROUND(SUM('Totals ELV'!Q11:T11),0) -> 16 | S11: =ROUND(SUM('Totals CRP'!Q11:T11),0) -> 16 | T11: =ROUND(SUM('Totals DQN'!Q11:T11),0) -> 2 | U11: 9 | V11: =ROUND(SUM('Totals Baseline'!V11:Y11),0) -> 9 | W11: =ROUND(SUM('Totals ELV'!V11:Y11),0) -> 2 | X11: =ROUND(SUM('Totals CRP'!V11:Y11),0) -> 0 | Y11: =ROUND(SUM('Totals DQN'!V11:Y11),0) -> 14 | Z11: 9 | AA11: =SUM('Totals Baseline'!AA11:AD11) -> 212.5 | AB11: =SUM('Totals ELV'!AA11:AD11) -> 202.95 | AC11: =SUM('Totals CRP'!AA11:AD11) -> 205.65 | AD11: =SUM('Totals DQN'!AA11:AD11) -> 113
A12: 10 | B12: =SUM('Totals Baseline'!B12:E12) -> 27 | C12: =SUM('Totals ELV'!B12:E12) -> 26 | D12: =SUM('Totals CRP'!B12:E12) -> 30.3 | E12: =SUM('Totals DQN'!B12:E12) -> 3 | F12: 10 | G12: =SUM('Totals Baseline'!G12:J12) -> 19 | H12: =SUM('Totals ELV'!G12:J12) -> 1.3 | I12: =SUM('Totals CRP'!G12:J12) -> 1 | J12: =SUM('Totals DQN'!G12:J12) -> 13 | K12: 10 | L12: =SUM('Totals Baseline'!L12:O12) -> 30 | M12: =SUM('Totals ELV'!L12:O12) -> 39.4 | N12: =SUM('Totals CRP'!L12:O12) -> 41.4 | O12: =SUM('Totals DQN'!L12:O12) -> 50 | P12: 10 | Q12: =ROUND(SUM('Totals Baseline'!Q12:T12),0) -> 14 | R12: =ROUND(SUM('Totals ELV'!Q12:T12),0) -> 15 | S12: =ROUND(SUM('Totals CRP'!Q12:T12),0) -> 15 | T12: =ROUND(SUM('Totals DQN'!Q12:T12),0) -> 2 | U12: 10 | V12: =ROUND(SUM('Totals Baseline'!V12:Y12),0) -> 19 | W12: =ROUND(SUM('Totals ELV'!V12:Y12),0) -> 1 | X12: =ROUND(SUM('Totals CRP'!V12:Y12),0) -> 1 | Y12: =ROUND(SUM('Totals DQN'!V12:Y12),0) -> 13 | Z12: 10 | AA12: =SUM('Totals Baseline'!AA12:AD12) -> 245 | AB12: =SUM('Totals ELV'!AA12:AD12) -> 219.7 | AC12: =SUM('Totals CRP'!AA12:AD12) -> 221.8 | AD12: =SUM('Totals DQN'!AA12:AD12) -> 127.5
A13: 11 | B13: =SUM('Totals Baseline'!B13:E13) -> 16 | C13: =SUM('Totals ELV'!B13:E13) -> 29 | D13: =SUM('Totals CRP'!B13:E13) -> 30.9 | E13: =SUM('Totals DQN'!B13:E13) -> 4 | F13: 11 | G13: =SUM('Totals Baseline'!G13:J13) -> 29 | H13: =SUM('Totals ELV'!G13:J13) -> 9.2 | I13: =SUM('Totals CRP'!G13:J13) -> 6.5 | J13: =SUM('Totals DQN'!G13:J13) -> 5 | K13: 11 | L13: =SUM('Totals Baseline'!L13:O13) -> 36 | M13: =SUM('Totals ELV'!L13:O13) -> 38.5 | N13: =SUM('Totals CRP'!L13:O13) -> 37.8 | O13: =SUM('Totals DQN'!L13:O13) -> 44 | P13: 11 | Q13: =ROUND(SUM('Totals Baseline'!Q13:T13),0) -> 8 | R13: =ROUND(SUM('Totals ELV'!Q13:T13),0) -> 16 | S13: =ROUND(SUM('Totals CRP'!Q13:T13),0) -> 15 | T13: =ROUND(SUM('Totals DQN'!Q13:T13),0) -> 2 | U13: 11 | V13: =ROUND(SUM('Totals Baseline'!V13:Y13),0) -> 29 | W13: =ROUND(SUM('Totals ELV'!V13:Y13),0) -> 9 | X13: =ROUND(SUM('Totals CRP'!V13:Y13),0) -> 7 | Y13: =ROUND(SUM('Totals DQN'!V13:Y13),0) -> 5 | Z13: 11 | AA13: =SUM('Totals Baseline'!AA13:AD13) -> 282 | AB13: =SUM('Totals ELV'!AA13:AD13) -> 244.6 | AC13: =SUM('Totals CRP'!AA13:AD13) -> 243.75 | AD13: =SUM('Totals DQN'!AA13:AD13) -> 134.5
... A38: 36 | B38: =SUM('Totals Baseline'!B38:E38) -> 0 | C38: =SUM('Totals ELV'!B38:E38) -> 34 | D38: =SUM('Totals CRP'!B38:E38) -> 42.9 | E38: =SUM('Totals DQN'!B38:E38) -> 70 | F38: 36 | G38: =SUM('Totals Baseline'!G38:J38) -> 85 | H38: =SUM('Totals ELV'!G38:J38) -> 3.9 | I38: =SUM('Totals CRP'!G38:J38) -> 0.8 | J38: =SUM('Totals DQN'!G38:J38) -> 0 | K38: 36 | L38: =SUM('Totals Baseline'!L38:O38) -> 45 | M38: =SUM('Totals ELV'!L38:O38) -> 25.7 | N38: =SUM('Totals CRP'!L38:O38) -> 28.1 | O38: =SUM('Totals DQN'!L38:O38) -> 15 | P38: 36 | Q38: =ROUND(SUM('Totals Baseline'!Q38:T38),0) -> 0 | R38: =ROUND(SUM('Totals ELV'!Q38:T38),0) -> 22 | S38: =ROUND(SUM('Totals CRP'!Q38:T38),0) -> 21 | T38: =ROUND(SUM('Totals DQN'!Q38:T38),0) -> 35 | U38: 36 | V38: =ROUND(SUM('Totals Baseline'!V38:Y38),0) -> 85 | W38: =ROUND(SUM('Totals ELV'!V38:Y38),0) -> 4 | X38: =ROUND(SUM('Totals CRP'!V38:Y38),0) -> 1 | Y38: =ROUND(SUM('Totals DQN'!V38:Y38),0) -> 0 | Z38: 36 | AA38: =SUM('Totals Baseline'!AA38:AD38) -> 2286 | AB38: =SUM('Totals ELV'!AA38:AD38) -> 891.05 | AC38: =SUM('Totals CRP'!AA38:AD38) -> 860.15 | AD38: =SUM('Totals DQN'!AA38:AD38) -> 788.5

Sheet Totals Baseline
A1: t | B1: Avg I Retailer | C1: Avg I Wholesaler | D1: Avg I Distributor | E1: Avg I Producer | F1: t | G1: Avg B Retailer | H1: Avg B Wholesaler | I1: Avg B Distributor | J1: Avg B Producer | K1: t | L1: Avg O Retailer | M1: Avg O Wholesaler | N1: Avg O Distributor | O1: Avg O Producer | P1: t | Q1: Avg ihc Retailer | R1: Avg ihc Wholesaler | S1: Avg ihc Distributor | T1: Avg ihc Producer | U1: t | V1: Avg ubc Retailer | W1: Avg ubc Wholesaler | X1: Avg ubc Distributor | Y1: Avg ubc Producer | Z1: t6 | AA1: Avg TC Retailer | AB1: Avg TC Wholesaler | AC1: Avg TC Distributor | AD1: Avg TC Producer
A2: 0 | B2: ='Inventory Baseline'!BA2 -> 12 | C2: ='Inventory Baseline'!BB2 -> 12 | D2: ='Inventory Baseline'!BC2 -> 12 | E2: ='Inventory Baseline'!BD2 -> 12 | F2: 0 | G2: ='Backlog Baseline'!BA2 -> 0 | H2: ='Backlog Baseline'!BB2 -> 0 | I2: ='Backlog Baseline'!BC2 -> 0 | J2: ='Backlog Baseline'!BD2 -> 0 | K2: 0 | L2: ='Orders Baseline'!AZ2 -> 0 | M2: ='Orders Baseline'!BA2 -> 0 | N2: ='Orders Baseline'!BB2 -> 0 | O2: ='Orders Baseline'!BC2 -> 0 | P2: 0 | Q2: =ROUND('IHC Baseline'!AY2,2) -> 0 | R2: =ROUND('IHC Baseline'!AZ2,2) -> 0 | S2: =ROUND('IHC Baseline'!BA2,2) -> 0 | T2: =ROUND('IHC Baseline'!BB2,2) -> 0 | U2: 0 | V2: =ROUND('UBC Baseline'!AZ2,2) -> 0 | W2: =ROUND('UBC Baseline'!BA2,2) -> 0 | X2: =ROUND('UBC Baseline'!BB2,2) -> 0 | Y2: =ROUND('UBC Baseline'!BC2,2) -> 0 | Z2: 0 | AA2: =Q2+V2 -> 0 | AB2: =R2+W2 -> 0 | AC2: =S2+X2 -> 0 | AD2: =T2+Y2 -> 0
A3: 1 | B3: ='Inventory Baseline'!BA3 -> 12 | C3: ='Inventory Baseline'!BB3 -> 12 | D3: ='Inventory Baseline'!BC3 -> 12 | E3: ='Inventory Baseline'!BD3 -> 12 | F3: 1 | G3: ='Backlog Baseline'!BA3 -> 0 | H3: ='Backlog Baseline'!BB3 -> 0 | I3: ='Backlog Baseline'!BC3 -> 0 | J3: ='Backlog Baseline'!BD3 -> 0 | K3: 1 | L3: ='Orders Baseline'!AZ3 -> 4 | M3: ='Orders Baseline'!BA3 -> 4 | N3: ='Orders Baseline'!BB3 -> 4 | O3: ='Orders Baseline'!BC3 -> 4 | P3: 1 | Q3: =ROUND('IHC Baseline'!AY3,2) -> 6 | R3: =ROUND('IHC Baseline'!AZ3,2) -> 6 | S3: =ROUND('IHC Baseline'!BA3,2) -> 6 | T3: =ROUND('IHC Baseline'!BB3,2) -> 6 | U3: 1 | V3: =ROUND('UBC Baseline'!AZ3,2) -> 0 | W3: =ROUND('UBC Baseline'!BA3,2) -> 0 | X3: =ROUND('UBC Baseline'!BB3,2) -> 0 | Y3: =ROUND('UBC Baseline'!BC3,2) -> 0 | Z3: 1 | AA3: =Q3+V3+AA2 -> 6 | AB3: =R3+W3+AB2 -> 6 | AC3: =S3+X3+AC2 -> 6 | AD3: =T3+Y3+AD2 -> 6
A4: 2 | B4: ='Inventory Baseline'!BA4 -> 12 | C4: ='Inventory Baseline'!BB4 -> 12 | D4: ='Inventory Baseline'!BC4 -> 12 | E4: ='Inventory Baseline'!BD4 -> 12 | F4: 2 | G4: ='Backlog Baseline'!BA4 -> 0 | H4: ='Backlog Baseline'!BB4 -> 0 | I4: ='Backlog Baseline'!BC4 -> 0 | J4: ='Backlog Baseline'!BD4 -> 0 | K4: 2 | L4: ='Orders Baseline'!AZ4 -> 4 | M4: ='Orders Baseline'!BA4 -> 4 | N4: ='Orders Baseline'!BB4 -> 4 | O4: ='Orders Baseline'!BC4 -> 4 | P4: 2 | Q4: =ROUND('IHC Baseline'!AY4,2) -> 6 | R4: =ROUND('IHC Baseline'!AZ4,2) -> 6 | S4: =ROUND('IHC Baseline'!BA4,2) -> 6 | T4: =ROUND('IHC Baseline'!BB4,2) -> 6 | U4: 2 | V4: =ROUND('UBC Baseline'!AZ4,2) -> 0 | W4: =ROUND('UBC Baseline'!BA4,2) -> 0 | X4: =ROUND('UBC Baseline'!BB4,2) -> 0 | Y4: =ROUND('UBC Baseline'!BC4,2) -> 0 | Z4: 2 | AA4: =Q4+V4+AA3 -> 12 | AB4: =R4+W4+AB3 -> 12 | AC4: =S4+X4+AC3 -> 12 | AD4: =T4+Y4+AD3 -> 12
A5: 3 | B5: ='Inventory Baseline'!BA5 -> 12 | C5: ='Inventory Baseline'!BB5 -> 12 | D5: ='Inventory Baseline'!BC5 -> 12 | E5: ='Inventory Baseline'!BD5 -> 12 | F5: 3 | G5: ='Backlog Baseline'!BA5 -> 0 | H5: ='Backlog Baseline'!BB5 -> 0 | I5: ='Backlog Baseline'!BC5 -> 0 | J5: ='Backlog Baseline'!BD5 -> 0 | K5: 3 | L5: ='Orders Baseline'!AZ5 -> 4 | M5: ='Orders Baseline'!BA5 -> 4 | N5: ='Orders Baseline'!BB5 -> 4 | O5: ='Orders Baseline'!BC5 -> 4 | P5: 3 | Q5: =ROUND('IHC Baseline'!AY5,2) -> 6 | R5: =ROUND('IHC Baseline'!AZ5,2) -> 6 | S5: =ROUND('IHC Baseline'!BA5,2) -> 6 | T5: =ROUND('IHC Baseline'!BB5,2) -> 6 | U5: 3 | V5: =ROUND('UBC Baseline'!AZ5,2) -> 0 | W5: =ROUND('UBC Baseline'!BA5,2) -> 0 | X5: =ROUND('UBC Baseline'!BB5,2) -> 0 | Y5: =ROUND('UBC Baseline'!BC5,2) -> 0 | Z5: 3 | AA5: =Q5+V5+AA4 -> 18 | AB5: =R5+W5+AB4 -> 18 | AC5: =S5+X5+AC4 -> 18 | AD5: =T5+Y5+AD4 -> 18
A6: 4 | B6: ='Inventory Baseline'!BA6 -> 12 | C6: ='Inventory Baseline'!BB6 -> 12 | D6: ='Inventory Baseline'!BC6 -> 12 | E6: ='Inventory Baseline'!BD6 -> 12 | F6: 4 | G6: ='Backlog Baseline'!BA6 -> 0 | H6: ='Backlog Baseline'!BB6 -> 0 | I6: ='Backlog Baseline'!BC6 -> 0 | J6: ='Backlog Baseline'!BD6 -> 0 | K6: 4 | L6: ='Orders Baseline'!AZ6 -> 4 | M6: ='Orders Baseline'!BA6 -> 4 | N6: ='Orders Baseline'!BB6 -> 4 | O6: ='Orders Baseline'!BC6 -> 4 | P6: 4 | Q6: =ROUND('IHC Baseline'!AY6,2) -> 6 | R6: =ROUND('IHC Baseline'!AZ6,2) -> 6 | S6: =ROUND('IHC Baseline'!BA6,2) -> 6 | T6: =ROUND('IHC Baseline'!BB6,2) -> 6 | U6: 4 | V6: =ROUND('UBC Baseline'!AZ6,2) -> 0 | W6: =ROUND('UBC Baseline'!BA6,2) -> 0 | X6: =ROUND('UBC Baseline'!BB6,2) -> 0 | Y6: =ROUND('UBC Baseline'!BC6,2) -> 0 | Z6: 4 | AA6: =Q6+V6+AA5 -> 24 | AB6: =R6+W6+AB5 -> 24 | AC6: =S6+X6+AC5 -> 24 | AD6: =T6+Y6+AD5 -> 24
A7: 5 | B7: ='Inventory Baseline'!BA7 -> 12 | C7: ='Inventory Baseline'!BB7 -> 12 | D7: ='Inventory Baseline'!BC7 -> 8 | E7: ='Inventory Baseline'!BD7 -> 12 | F7: 5 | G7: ='Backlog Baseline'!BA7 -> 0 | H7: ='Backlog Baseline'!BB7 -> 0 | I7: ='Backlog Baseline'!BC7 -> 0 | J7: ='Backlog Baseline'!BD7 -> 0 | K7: 5 | L7: ='Orders Baseline'!AZ7 -> 8 | M7: ='Orders Baseline'!BA7 -> 4 | N7: ='Orders Baseline'!BB7 -> 4 | O7: ='Orders Baseline'!BC7 -> 4 | P7: 5 | Q7: =ROUND('IHC Baseline'!AY7,2) -> 6 | R7: =ROUND('IHC Baseline'!AZ7,2) -> 6 | S7: =ROUND('IHC Baseline'!BA7,2) -> 4 | T7: =ROUND('IHC Baseline'!BB7,2) -> 6 | U7: 5 | V7: =ROUND('UBC Baseline'!AZ7,2) -> 0 | W7: =ROUND('UBC Baseline'!BA7,2) -> 0 | X7: =ROUND('UBC Baseline'!BB7,2) -> 0 | Y7: =ROUND('UBC Baseline'!BC7,2) -> 0 | Z7: 5 | AA7: =Q7+V7+AA6 -> 30 | AB7: =R7+W7+AB6 -> 30 | AC7: =S7+X7+AC6 -> 28 | AD7: =T7+Y7+AD6 -> 30
A8: 6 | B8: ='Inventory Baseline'!BA8 -> 12 | C8: ='Inventory Baseline'!BB8 -> 12 | D8: ='Inventory Baseline'!BC8 -> 4 | E8: ='Inventory Baseline'!BD8 -> 12 | F8: 6 | G8: ='Backlog Baseline'!BA8 -> 0 | H8: ='Backlog Baseline'!BB8 -> 0 | I8: ='Backlog Baseline'!BC8 -> 0 | J8: ='Backlog Baseline'!BD8 -> 0 | K8: 6 | L8: ='Orders Baseline'!AZ8 -> 8 | M8: ='Orders Baseline'!BA8 -> 0 | N8: ='Orders Baseline'!BB8 -> 4 | O8: ='Orders Baseline'!BC8 -> 0 | P8: 6 | Q8: =ROUND('IHC Baseline'!AY8,2) -> 6 | R8: =ROUND('IHC Baseline'!AZ8,2) -> 6 | S8: =ROUND('IHC Baseline'!BA8,2) -> 2 | T8: =ROUND('IHC Baseline'!BB8,2) -> 6 | U8: 6 | V8: =ROUND('UBC Baseline'!AZ8,2) -> 0 | W8: =ROUND('UBC Baseline'!BA8,2) -> 0 | X8: =ROUND('UBC Baseline'!BB8,2) -> 0 | Y8: =ROUND('UBC Baseline'!BC8,2) -> 0 | Z8: 6 | AA8: =Q8+V8+AA7 -> 36 | AB8: =R8+W8+AB7 -> 36 | AC8: =S8+X8+AC7 -> 30 | AD8: =T8+Y8+AD7 -> 36
A9: 7 | B9: ='Inventory Baseline'!BA9 -> 16 | C9: ='Inventory Baseline'!BB9 -> 16 | D9: ='Inventory Baseline'!BC9 -> 0 | E9: ='Inventory Baseline'!BD9 -> 12 | F9: 7 | G9: ='Backlog Baseline'!BA9 -> 0 | H9: ='Backlog Baseline'!BB9 -> 0 | I9: ='Backlog Baseline'!BC9 -> 0 | J9: ='Backlog Baseline'!BD9 -> 0 | K9: 7 | L9: ='Orders Baseline'!AZ9 -> 8 | M9: ='Orders Baseline'!BA9 -> 0 | N9: ='Orders Baseline'!BB9 -> 8 | O9: ='Orders Baseline'!BC9 -> 0 | P9: 7 | Q9: =ROUND('IHC Baseline'!AY9,2) -> 8 | R9: =ROUND('IHC Baseline'!AZ9,2) -> 8 | S9: =ROUND('IHC Baseline'!BA9,2) -> 0 | T9: =ROUND('IHC Baseline'!BB9,2) -> 6 | U9: 7 | V9: =ROUND('UBC Baseline'!AZ9,2) -> 0 | W9: =ROUND('UBC Baseline'!BA9,2) -> 0 | X9: =ROUND('UBC Baseline'!BB9,2) -> 0 | Y9: =ROUND('UBC Baseline'!BC9,2) -> 0 | Z9: 7 | AA9: =Q9+V9+AA8 -> 44 | AB9: =R9+W9+AB8 -> 44 | AC9: =S9+X9+AC8 -> 30 | AD9: =T9+Y9+AD8 -> 42
A10: 8 | B10: ='Inventory Baseline'!BA10 -> 20 | C10: ='Inventory Baseline'!BB10 -> 16 | D10: ='Inventory Baseline'!BC10 -> 0 | E10: ='Inventory Baseline'!BD10 -> 8 | F10: 8 | G10: ='Backlog Baseline'!BA10 -> 0 | H10: ='Backlog Baseline'!BB10 -> 0 | I10: ='Backlog Baseline'!BC10 -> 4 | J10: ='Backlog Baseline'!BD10 -> 0 | K10: 8 | L10: ='Orders Baseline'!AZ10 -> 8 | M10: ='Orders Baseline'!BA10 -> 0 | N10: ='Orders Baseline'!BB10 -> 9 | O10: ='Orders Baseline'!BC10 -> 1 | P10: 8 | Q10: =ROUND('IHC Baseline'!AY10,2) -> 10 | R10: =ROUND('IHC Baseline'!AZ10,2) -> 8 | S10: =ROUND('IHC Baseline'!BA10,2) -> 0 | T10: =ROUND('IHC Baseline'!BB10,2) -> 4 | U10: 8 | V10: =ROUND('UBC Baseline'!AZ10,2) -> 0 | W10: =ROUND('UBC Baseline'!BA10,2) -> 0 | X10: =ROUND('UBC Baseline'!BB10,2) -> 4 | Y10: =ROUND('UBC Baseline'!BC10,2) -> 0 | Z10: 8 | AA10: =Q10+V10+AA9 -> 54 | AB10: =R10+W10+AB9 -> 52 | AC10: =S10+X10+AC9 -> 34 | AD10: =T10+Y10+AD9 -> 46
A11: 9 | B11: ='Inventory Baseline'!BA11 -> 19 | C11: ='Inventory Baseline'!BB11 -> 16 | D11: ='Inventory Baseline'!BC11 -> 0 | E11: ='Inventory Baseline'!BD11 -> 0 | F11: 9 | G11: ='Backlog Baseline'!BA11 -> 0 | H11: ='Backlog Baseline'!BB11 -> 0 | I11: ='Backlog Baseline'!BC11 -> 8 | J11: ='Backlog Baseline'!BD11 -> 1 | K11: 9 | L11: ='Orders Baseline'!AZ11 -> 8 | M11: ='Orders Baseline'!BA11 -> 0 | N11: ='Orders Baseline'!BB11 -> 10 | O11: ='Orders Baseline'!BC11 -> 8 | P11: 9 | Q11: =ROUND('IHC Baseline'!AY11,2) -> 9.5 | R11: =ROUND('IHC Baseline'!AZ11,2) -> 8 | S11: =ROUND('IHC Baseline'!BA11,2) -> 0 | T11: =ROUND('IHC Baseline'!BB11,2) -> 0 | U11: 9 | V11: =ROUND('UBC Baseline'!AZ11,2) -> 0 | W11: =ROUND('UBC Baseline'!BA11,2) -> 0 | X11: =ROUND('UBC Baseline'!BB11,2) -> 8 | Y11: =ROUND('UBC Baseline'!BC11,2) -> 1 | Z11: 9 | AA11: =Q11+V11+AA10 -> 63.5 | AB11: =R11+W11+AB10 -> 60 | AC11: =S11+X11+AC10 -> 42 | AD11: =T11+Y11+AD10 -> 47
A12: 10 | B12: ='Inventory Baseline'!BA12 -> 11 | C12: ='Inventory Baseline'!BB12 -> 16 | D12: ='Inventory Baseline'!BC12 -> 0 | E12: ='Inventory Baseline'!BD12 -> 0 | F12: 10 | G12: ='Backlog Baseline'!BA12 -> 0 | H12: ='Backlog Baseline'!BB12 -> 0 | I12: ='Backlog Baseline'!BC12 -> 8 | J12: ='Backlog Baseline'!BD12 -> 11 | K12: 10 | L12: ='Orders Baseline'!AZ12 -> 8 | M12: ='Orders Baseline'!BA12 -> 0 | N12: ='Orders Baseline'!BB12 -> 10 | O12: ='Orders Baseline'!BC12 -> 12 | P12: 10 | Q12: =ROUND('IHC Baseline'!AY12,2) -> 5.5 | R12: =ROUND('IHC Baseline'!AZ12,2) -> 8 | S12: =ROUND('IHC Baseline'!BA12,2) -> 0 | T12: =ROUND('IHC Baseline'!BB12,2) -> 0 | U12: 10 | V12: =ROUND('UBC Baseline'!AZ12,2) -> 0 | W12: =ROUND('UBC Baseline'!BA12,2) -> 0 | X12: =ROUND('UBC Baseline'!BB12,2) -> 8 | Y12: =ROUND('UBC Baseline'!BC12,2) -> 11 | Z12: 10 | AA12: =Q12+V12+AA11 -> 69 | AB12: =R12+W12+AB11 -> 68 | AC12: =S12+X12+AC11 -> 50 | AD12: =T12+Y12+AD11 -> 58
A13: 11 | B13: ='Inventory Baseline'!BA13 -> 0 | C13: ='Inventory Baseline'!BB13 -> 16 | D13: ='Inventory Baseline'!BC13 -> 0 | E13: ='Inventory Baseline'!BD13 -> 0 | F13: 11 | G13: ='Backlog Baseline'!BA13 -> 1 | H13: ='Backlog Baseline'!BB13 -> 0 | I13: ='Backlog Baseline'!BC13 -> 8 | J13: ='Backlog Baseline'!BD13 -> 20 | K13: 11 | L13: ='Orders Baseline'!AZ13 -> 8 | M13: ='Orders Baseline'!BA13 -> 3 | N13: ='Orders Baseline'!BB13 -> 10 | O13: ='Orders Baseline'!BC13 -> 15 | P13: 11 | Q13: =ROUND('IHC Baseline'!AY13,2) -> 0 | R13: =ROUND('IHC Baseline'!AZ13,2) -> 8 | S13: =ROUND('IHC Baseline'!BA13,2) -> 0 | T13: =ROUND('IHC Baseline'!BB13,2) -> 0 | U13: 11 | V13: =ROUND('UBC Baseline'!AZ13,2) -> 1 | W13: =ROUND('UBC Baseline'!BA13,2) -> 0 | X13: =ROUND('UBC Baseline'!BB13,2) -> 8 | Y13: =ROUND('UBC Baseline'!BC13,2) -> 20 | Z13: 11 | AA13: =Q13+V13+AA12 -> 70 | AB13: =R13+W13+AB12 -> 76 | AC13: =S13+X13+AC12 -> 58 | AD13: =T13+Y13+AD12 -> 78
A14: 12 | B14: ='Inventory Baseline'!BA14 -> 0 | C14: ='Inventory Baseline'!BB14 -> 13 | D14: ='Inventory Baseline'!BC14 -> 0 | E14: ='Inventory Baseline'!BD14 -> 0 | F14: 12 | G14: ='Backlog Baseline'!BA14 -> 16 | H14: ='Backlog Baseline'!BB14 -> 0 | I14: ='Backlog Baseline'!BC14 -> 16 | J14: ='Backlog Baseline'!BD14 -> 22 | K14: 12 | L14: ='Orders Baseline'!AZ14 -> 8 | M14: ='Orders Baseline'!BA14 -> 15 | N14: ='Orders Baseline'!BB14 -> 9 | O14: ='Orders Baseline'!BC14 -> 16 | P14: 12 | Q14: =ROUND('IHC Baseline'!AY14,2) -> 0 | R14: =ROUND('IHC Baseline'!AZ14,2) -> 6.5 | S14: =ROUND('IHC Baseline'!BA14,2) -> 0 | T14: =ROUND('IHC Baseline'!BB14,2) -> 0 | U14: 12 | V14: =ROUND('UBC Baseline'!AZ14,2) -> 16 | W14: =ROUND('UBC Baseline'!BA14,2) -> 0 | X14: =ROUND('UBC Baseline'!BB14,2) -> 16 | Y14: =ROUND('UBC Baseline'!BC14,2) -> 22 | Z14: 12 | AA14: =Q14+V14+AA13 -> 86 | AB14: =R14+W14+AB13 -> 82.5 | AC14: =S14+X14+AC13 -> 74 | AD14: =T14+Y14+AD13 -> 100
... A38: 36 | B38: ='Inventory Baseline'!BA38 -> 0 | C38: ='Inventory Baseline'!BB38 -> 0 | D38: ='Inventory Baseline'!BC38 -> 0 | E38: ='Inventory Baseline'!BD38 -> 0 | F38: 36 | G38: ='Backlog Baseline'!BA38 -> 29 | H38: ='Backlog Baseline'!BB38 -> 20 | I38: ='Backlog Baseline'!BC38 -> 11 | J38: ='Backlog Baseline'!BD38 -> 25 | K38: 36 | L38: ='Orders Baseline'!AZ38 -> 8 | M38: ='Orders Baseline'!BA38 -> 19 | N38: ='Orders Baseline'!BB38 -> 8 | O38: ='Orders Baseline'!BC38 -> 10 | P38: 36 | Q38: =ROUND('IHC Baseline'!AY38,2) -> 0 | R38: =ROUND('IHC Baseline'!AZ38,2) -> 0 | S38: =ROUND('IHC Baseline'!BA38,2) -> 0 | T38: =ROUND('IHC Baseline'!BB38,2) -> 0 | U38: 36 | V38: =ROUND('UBC Baseline'!AZ38,2) -> 29 | W38: =ROUND('UBC Baseline'!BA38,2) -> 20 | X38: =ROUND('UBC Baseline'!BB38,2) -> 11 | Y38: =ROUND('UBC Baseline'!BC38,2) -> 25 | Z38: 36 | AA38: =Q38+V38+AA37 -> 634 | AB38: =R38+W38+AB37 -> 535.5 | AC38: =S38+X38+AC37 -> 516.5 | AD38: =T38+Y38+AD37 -> 600

Sheet Graphs Baseline

Sheet Inventory Baseline
A1: t | B1: i_d | C1: i_f | D1: i_r | E1: i_w | G1: i_d | H1: i_f | I1: i_r | J1: i_w | L1: i_d | M1: i_f | N1: i_r | O1: i_w | Q1: i_d | R1: i_f | S1: i_r | T1: i_w | V1: i_d | W1: i_f | X1: i_r | Y1: i_w | AA1: i_d | AB1: i_f | AC1: i_r | AD1: i_w | AF1: i_d | AG1: i_f | AH1: i_r | AI1: i_w | AK1: i_d | AL1: i_f | AM1: i_r | AN1: i_w | AP1: i_d | AQ1: i_f | AR1: i_r | AS1: i_w | AU1: i_d | AV1: i_f | AW1: i_r | AX1: i_w | BA1: Avg I Retailer | BB1: Avg I Wholesaler | BC1: Avg I Distributor | BD1: Avg I Producer
A2: 0 | B2: 12 | C2: 12 | D2: 12 | E2: 12 | G2: 12 | H2: 12 | I2: 12 | J2: 12 | L2: 12 | M2: 12 | N2: 12 | O2: 12 | Q2: 12 | R2: 12 | S2: 12 | T2: 12 | V2: 12 | W2: 12 | X2: 12 | Y2: 12 | AA2: 12 | AB2: 12 | AC2: 12 | AD2: 12 | AF2: 12 | AG2: 12 | AH2: 12 | AI2: 12 | AK2: 12 | AL2: 12 | AM2: 12 | AN2: 12 | AP2: 12 | AQ2: 12 | AR2: 12 | AS2: 12 | AU2: 12 | AV2: 12 | AW2: 12 | AX2: 12 | BA2: =AVERAGE(B2,G2,L2,Q2,V2,AA2,AF2,AK2,AP2,AU2) -> 12 | BB2: =AVERAGE(C2,H2,M2,R2,W2,AB2,AG2,AL2,AQ2,AV2) -> 12 | BC2: =AVERAGE(D2,I2,N2,S2,X2,AC2,AH2,AM2,AR2,AW2) -> 12 | BD2: =AVERAGE(E2,J2,O2,T2,Y2,AD2,AI2,AN2,AS2,AX2) -> 12
A3: 1 | B3: 12 | C3: 12 | D3: 12 | E3: 12 | G3: 12 | H3: 12 | I3: 12 | J3: 12 | L3: 12 | M3: 12 | N3: 12 | O3: 12 | Q3: 12 | R3: 12 | S3: 12 | T3: 12 | V3: 12 | W3: 12 | X3: 12 | Y3: 12 | AA3: 12 | AB3: 12 | AC3: 12 | AD3: 12 | AF3: 12 | AG3: 12 | AH3: 12 | AI3: 12 | AK3: 12 | AL3: 12 | AM3: 12 | AN3: 12 | AP3: 12 | AQ3: 12 | AR3: 12 | AS3: 12 | AU3: 12 | AV3: 12 | AW3: 12 | AX3: 12 | BA3: =AVERAGE(B3,G3,L3,Q3,V3,AA3,AF3,AK3,AP3,AU3) -> 12 | BB3: =AVERAGE(C3,H3,M3,R3,W3,AB3,AG3,AL3,AQ3,AV3) -> 12 | BC3: =AVERAGE(D3,I3,N3,S3,X3,AC3,AH3,AM3,AR3,AW3) -> 12 | BD3: =AVERAGE(E3,J3,O3,T3,Y3,AD3,AI3,AN3,AS3,AX3) -> 12
A4: 2 | B4: 12 | C4: 12 | D4: 12 | E4: 12 | G4: 12 | H4: 12 | I4: 12 | J4: 12 | L4: 12 | M4: 12 | N4: 12 | O4: 12 | Q4: 12 | R4: 12 | S4: 12 | T4: 12 | V4: 12 | W4: 12 | X4: 12 | Y4: 12 | AA4: 12 | AB4: 12 | AC4: 12 | AD4: 12 | AF4: 12 | AG4: 12 | AH4: 12 | AI4: 12 | AK4: 12 | AL4: 12 | AM4: 12 | AN4: 12 | AP4: 12 | AQ4: 12 | AR4: 12 | AS4: 12 | AU4: 12 | AV4: 12 | AW4: 12 | AX4: 12 | BA4: =AVERAGE(B4,G4,L4,Q4,V4,AA4,AF4,AK4,AP4,AU4) -> 12 | BB4: =AVERAGE(C4,H4,M4,R4,W4,AB4,AG4,AL4,AQ4,AV4) -> 12 | BC4: =AVERAGE(D4,I4,N4,S4,X4,AC4,AH4,AM4,AR4,AW4) -> 12 | BD4: =AVERAGE(E4,J4,O4,T4,Y4,AD4,AI4,AN4,AS4,AX4) -> 12
A5: 3 | B5: 12 | C5: 12 | D5: 12 | E5: 12 | G5: 12 | H5: 12 | I5: 12 | J5: 12 | L5: 12 | M5: 12 | N5: 12 | O5: 12 | Q5: 12 | R5: 12 | S5: 12 | T5: 12 | V5: 12 | W5: 12 | X5: 12 | Y5: 12 | AA5: 12 | AB5: 12 | AC5: 12 | AD5: 12 | AF5: 12 | AG5: 12 | AH5: 12 | AI5: 12 | AK5: 12 | AL5: 12 | AM5: 12 | AN5: 12 | AP5: 12 | AQ5: 12 | AR5: 12 | AS5: 12 | AU5: 12 | AV5: 12 | AW5: 12 | AX5: 12 | BA5: =AVERAGE(B5,G5,L5,Q5,V5,AA5,AF5,AK5,AP5,AU5) -> 12 | BB5: =AVERAGE(C5,H5,M5,R5,W5,AB5,AG5,AL5,AQ5,AV5) -> 12 | BC5: =AVERAGE(D5,I5,N5,S5,X5,AC5,AH5,AM5,AR5,AW5) -> 12 | BD5: =AVERAGE(E5,J5,O5,T5,Y5,AD5,AI5,AN5,AS5,AX5) -> 12
A6: 4 | B6: 12 | C6: 12 | D6: 12 | E6: 12 | G6: 12 | H6: 12 | I6: 12 | J6: 12 | L6: 12 | M6: 12 | N6: 12 | O6: 12 | Q6: 12 | R6: 12 | S6: 12 | T6: 12 | V6: 12 | W6: 12 | X6: 12 | Y6: 12 | AA6: 12 | AB6: 12 | AC6: 12 | AD6: 12 | AF6: 12 | AG6: 12 | AH6: 12 | AI6: 12 | AK6: 12 | AL6: 12 | AM6: 12 | AN6: 12 | AP6: 12 | AQ6: 12 | AR6: 12 | AS6: 12 | AU6: 12 | AV6: 12 | AW6: 12 | AX6: 12 | BA6: =AVERAGE(B6,G6,L6,Q6,V6,AA6,AF6,AK6,AP6,AU6) -> 12 | BB6: =AVERAGE(C6,H6,M6,R6,W6,AB6,AG6,AL6,AQ6,AV6) -> 12 | BC6: =AVERAGE(D6,I6,N6,S6,X6,AC6,AH6,AM6,AR6,AW6) -> 12 | BD6: =AVERAGE(E6,J6,O6,T6,Y6,AD6,AI6,AN6,AS6,AX6) -> 12
A7: 5 | B7: 12 | C7: 12 | D7: 8 | E7: 12 | G7: 12 | H7: 12 | I7: 8 | J7: 12 | L7: 12 | M7: 12 | N7: 8 | O7: 12 | Q7: 12 | R7: 12 | S7: 8 | T7: 12 | V7: 12 | W7: 12 | X7: 8 | Y7: 12 | AA7: 12 | AB7: 12 | AC7: 8 | AD7: 12 | AF7: 12 | AG7: 12 | AH7: 8 | AI7: 12 | AK7: 12 | AL7: 12 | AM7: 8 | AN7: 12 | AP7: 12 | AQ7: 12 | AR7: 8 | AS7: 12 | AU7: 12 | AV7: 12 | AW7: 8 | AX7: 12 | BA7: =AVERAGE(B7,G7,L7,Q7,V7,AA7,AF7,AK7,AP7,AU7) -> 12 | BB7: =AVERAGE(C7,H7,M7,R7,W7,AB7,AG7,AL7,AQ7,AV7) -> 12 | BC7: =AVERAGE(D7,I7,N7,S7,X7,AC7,AH7,AM7,AR7,AW7) -> 8 | BD7: =AVERAGE(E7,J7,O7,T7,Y7,AD7,AI7,AN7,AS7,AX7) -> 12
A8: 6 | B8: 12 | C8: 12 | D8: 4 | E8: 12 | G8: 12 | H8: 12 | I8: 4 | J8: 12 | L8: 12 | M8: 12 | N8: 4 | O8: 12 | Q8: 12 | R8: 12 | S8: 4 | T8: 12 | V8: 12 | W8: 12 | X8: 4 | Y8: 12 | AA8: 12 | AB8: 12 | AC8: 4 | AD8: 12 | AF8: 12 | AG8: 12 | AH8: 4 | AI8: 12 | AK8: 12 | AL8: 12 | AM8: 4 | AN8: 12 | AP8: 12 | AQ8: 12 | AR8: 4 | AS8: 12 | AU8: 12 | AV8: 12 | AW8: 4 | AX8: 12 | BA8: =AVERAGE(B8,G8,L8,Q8,V8,AA8,AF8,AK8,AP8,AU8) -> 12 | BB8: =AVERAGE(C8,H8,M8,R8,W8,AB8,AG8,AL8,AQ8,AV8) -> 12 | BC8: =AVERAGE(D8,I8,N8,S8,X8,AC8,AH8,AM8,AR8,AW8) -> 4 | BD8: =AVERAGE(E8,J8,O8,T8,Y8,AD8,AI8,AN8,AS8,AX8) -> 12
A9: 7 | B9: 16 | C9: 16 | D9: 0 | E9: 12 | G9: 16 | H9: 16 | I9: 0 | J9: 12 | L9: 16 | M9: 16 | N9: 0 | O9: 12 | Q9: 16 | R9: 16 | S9: 0 | T9: 12 | V9: 16 | W9: 16 | X9: 0 | Y9: 12 | AA9: 16 | AB9: 16 | AC9: 0 | AD9: 12 | AF9: 16 | AG9: 16 | AH9: 0 | AI9: 12 | AK9: 16 | AL9: 16 | AM9: 0 | AN9: 12 | AP9: 16 | AQ9: 16 | AR9: 0 | AS9: 12 | AU9: 16 | AV9: 16 | AW9: 0 | AX9: 12 | BA9: =AVERAGE(B9,G9,L9,Q9,V9,AA9,AF9,AK9,AP9,AU9) -> 16 | BB9: =AVERAGE(C9,H9,M9,R9,W9,AB9,AG9,AL9,AQ9,AV9) -> 16 | BC9: =AVERAGE(D9,I9,N9,S9,X9,AC9,AH9,AM9,AR9,AW9) -> 0 | BD9: =AVERAGE(E9,J9,O9,T9,Y9,AD9,AI9,AN9,AS9,AX9) -> 12
A10: 8 | B10: 20 | C10: 16 | D10: 0 | E10: 8 | G10: 20 | H10: 16 | I10: 0 | J10: 8 | L10: 20 | M10: 16 | N10: 0 | O10: 8 | Q10: 20 | R10: 16 | S10: 0 | T10: 8 | V10: 20 | W10: 16 | X10: 0 | Y10: 8 | AA10: 20 | AB10: 16 | AC10: 0 | AD10: 8 | AF10: 20 | AG10: 16 | AH10: 0 | AI10: 8 | AK10: 20 | AL10: 16 | AM10: 0 | AN10: 8 | AP10: 20 | AQ10: 16 | AR10: 0 | AS10: 8 | AU10: 20 | AV10: 16 | AW10: 0 | AX10: 8 | BA10: =AVERAGE(B10,G10,L10,Q10,V10,AA10,AF10,AK10,AP10,AU10) -> 20 | BB10: =AVERAGE(C10,H10,M10,R10,W10,AB10,AG10,AL10,AQ10,AV10) -> 16 | BC10: =AVERAGE(D10,I10,N10,S10,X10,AC10,AH10,AM10,AR10,AW10) -> 0 | BD10: =AVERAGE(E10,J10,O10,T10,Y10,AD10,AI10,AN10,AS10,AX10) -> 8
A11: 9 | B11: 19 | C11: 16 | D11: 0 | E11: 0 | G11: 19 | H11: 16 | I11: 0 | J11: 0 | L11: 19 | M11: 16 | N11: 0 | O11: 0 | Q11: 19 | R11: 16 | S11: 0 | T11: 0 | V11: 19 | W11: 16 | X11: 0 | Y11: 0 | AA11: 19 | AB11: 16 | AC11: 0 | AD11: 0 | AF11: 19 | AG11: 16 | AH11: 0 | AI11: 0 | AK11: 19 | AL11: 16 | AM11: 0 | AN11: 0 | AP11: 19 | AQ11: 16 | AR11: 0 | AS11: 0 | AU11: 19 | AV11: 16 | AW11: 0 | AX11: 0 | BA11: =AVERAGE(B11,G11,L11,Q11,V11,AA11,AF11,AK11,AP11,AU11) -> 19 | BB11: =AVERAGE(C11,H11,M11,R11,W11,AB11,AG11,AL11,AQ11,AV11) -> 16 | BC11: =AVERAGE(D11,I11,N11,S11,X11,AC11,AH11,AM11,AR11,AW11) -> 0 | BD11: =AVERAGE(E11,J11,O11,T11,Y11,AD11,AI11,AN11,AS11,AX11) -> 0
A12: 10 | B12: 11 | C12: 16 | D12: 0 | E12: 0 | G12: 11 | H12: 16 | I12: 0 | J12: 0 | L12: 11 | M12: 16 | N12: 0 | O12: 0 | Q12: 11 | R12: 16 | S12: 0 | T12: 0 | V12: 11 | W12: 16 | X12: 0 | Y12: 0 | AA12: 11 | AB12: 16 | AC12: 0 | AD12: 0 | AF12: 11 | AG12: 16 | AH12: 0 | AI12: 0 | AK12: 11 | AL12: 16 | AM12: 0 | AN12: 0 | AP12: 11 | AQ12: 16 | AR12: 0 | AS12: 0 | AU12: 11 | AV12: 16 | AW12: 0 | AX12: 0 | BA12: =AVERAGE(B12,G12,L12,Q12,V12,AA12,AF12,AK12,AP12,AU12) -> 11 | BB12: =AVERAGE(C12,H12,M12,R12,W12,AB12,AG12,AL12,AQ12,AV12) -> 16 | BC12: =AVERAGE(D12,I12,N12,S12,X12,AC12,AH12,AM12,AR12,AW12) -> 0 | BD12: =AVERAGE(E12,J12,O12,T12,Y12,AD12,AI12,AN12,AS12,AX12) -> 0
